Workbook

Sheet Master_Requirements
A1: Req ID | B1: Requirement / Source Objective | C1: Requirement Statement | D1: Source Basis | E1: IAT Coverage | F1: Evidence / Verification | G1: Situational Analysis Output | H1: Draft MOO Output | I1: Platform Requirement / UX Workflow | J1: Core Data Entities | K1: Priority / Escalation Rule | L1: Priority
A2: MR-01 | B2: Project objective: validated actionable MOO | C2: Create one integrated, evidence-based operating framework linking CDRRMO institutional functions and EOC incident coordination. | D2: Inception Report Objectives 1–5; IAT v1.1 purpose/use | E2: All 140 indicators (125 core in Parts A–B; 15 interface in Part C) | F2: Validated evidence register; scored baseline; priority gaps | G2: Executive Summary; methodology; consolidated findings; priority actions | H2: Integrated MOO architecture; procedures, standards, roles, forms and update mechanism | I2: Role-based assessment workflow; evidence-first scoring; traceability view | J2: Assessment cycle; evidence; scores; gaps; actions; MOO traceability; document versions | K2: Applies to the whole assessment | L2: Critical
A3: MR-02 | B3: Functional Area 1 | C3: Define mandate, organization, authority, delegation, roles, coordination and accountability. | D3: MOO Functional Area 1; A1, A2, A10 | E3: A1.1–A1.8; A2.1–A2.10; A10.1–A10.3 | F3: Legal instruments, organogram, plantilla, rosters, MOAs, reporting records, skills inventory | G3: Governance/institutional findings | H3: Ch.1–2; Ch.9 partnerships; role/JD annexes | I3: Governance module; role matrix; approval workflow | J3: organizations; offices; positions; authorities; partnerships; declarations; skills_inventory | K3: High when mandatory legal/role gaps score below 3 | L3: High
A4: MR-03 | B4: Functional Area 2 | C4: Maintain current multi-hazard risk intelligence, prevention/mitigation and risk-informed planning. | D4: MOO Functional Area 2; A3, A5; Part C C1–C3 | E4: A3.1–A3.7; A5.1–A5.9; interface C1.1–C1.4, C2.1–C2.3, C3.1–C3.3 | F4: Plans, hazard maps, CDRA, GIS/data records, critical-facility dependency map, dataset version dates; lead-office records for Part C | G4: Risk and planning baseline; Part C interface results | H4: Ch.3 Planning; Ch.7 Knowledge Management | I4: GIS/risk dashboard; document/version control; failure-chain view | J4: plans; hazards; risk_scenarios; gis_layers; datasets; critical_facilities; facility_dependencies | K4: Risk-informed prioritization | L4: High
A5: MR-04 | B5: Functional Area 3 | C5: Establish preparedness, contingency planning, capacity development, drills and readiness standards. | D5: MOO Functional Area 3; A3, A7, B7; Part C C5 | E5: A3.3–A3.6; A7.1–A7.9; B7.2–B7.6; interface C5.1 | F5: CPs, PSCP, training, refresher and drill records, EC audits, stock records, welfare-check drills | G5: Preparedness capacity and readiness gaps | H5: Ch.3 Planning; Ch.4; Ch.6 Capacity; EOC Ch.8–9 | I5: Preparedness dashboard; training/exercise calendar; refresher tracking | J5: plans; training; exercises; evacuation_centers; inventories; welfare_checks | K5: High for untested mandatory readiness | L5: High
A6: MR-05 | B6: Functional Area 4 | C6: Define EOC activation/deactivation, incident management, ICS interface, escalation, transition and anticipatory action. | D6: MOO Functional Area 4; B1, B4, B7.1, A8; A1.8; Part C C4 | E6: A1.8; A8.1–A8.9; B1.1–B1.5; B4.1–B4.2; B7.1; interface C4.1–C4.4 | F6: ICS EO, IMT roster, activation matrix/logs, EOC organogram and roster with alternates, approved EOC SOPs, PDRA records, AA protocols, sector AA plans | G6: EOC/response readiness baseline | H6: Ch.4 Response; EOC Ch.1–2; EOC Ch.7 | I6: Activation wizard; operational-period workflow; ICS/EOC role view; AA protocol checklist | J6: activation_levels; activation_events; incidents; imt_rosters; aa_protocols | K6: Immediate escalation for mandatory activation/ICS/AA gaps | L6: Critical
A7: MR-06 | B7: Functional Area 5 | C7: Operate hazard monitoring, warning thresholds, last-mile dissemination, emergency communications and public information. | D7: MOO Functional Area 5; A6, B3 | E7: A6.1–A6.7; B3.1–B3.6 | F7: EWS logs, warning matrix, test logs, comms inventory, directory, declaration/AA advisory templates | G7: Warning/communications findings | H7: Ch.4; EOC Ch.3–4; EOC Ch.5 | I7: Warning composer; dissemination log; channel status | J7: warning_systems; thresholds; messages; channels; communication_assets; network_tests; advisory_templates | K7: Life-safety priority; weight-3 mandatory gaps | L7: Critical
A8: MR-07 | B8: Functional Area 6 | C8: Maintain situational awareness, information management, GIS/COP, SitReps and reporting flows. | D8: MOO Functional Area 6; B5, A5, A10 | E8: A5.1–A5.9; A10.3–A10.8; B5.1–B5.7 | F8: GIS layers, SitReps, logs, monitoring records, reports, 45-day RA 12287 reports, citizen-report intake logs | G8: Information-system and reporting baseline | H8: Ch.7; EOC Ch.5–6 | I8: Common Operating Picture; reporting workflow; audit trail; verified citizen-report intake | J8: sit_reps; cop_layers; event_logs; reports; hazard_feeds; citizen_reports; declaration_reports | K8: Data quality/completeness and timeliness | L8: High
A9: MR-08 | B9: Functional Area 7 | C9: Provide resource, logistics and emergency support management, including procurement, stockpiling, prepositioning and mutual aid. | D9: MOO Functional Area 7; A4, A7, A8, B6 | E9: A4.1–A4.9; A7.5; A8.3; A8.8; B6.1–B6.6 | F9: Budget/fund records incl. AA line, procurement SOPs, inventories, resource requests, MOAs, supplier agreements | G9: Resource and financial capacity findings | H9: Ch.5 Financing; EOC Ch.6–7 | I9: Resource request/approval/tracking; logistics dashboard; AA fund tracker | J9: budgets; resources; warehouses; resource_requests; mutual_aid; resource_commitments; aa_fund_allocations | K9: High for legal/fund/resource bottlenecks | L9: High
A10: MR-09 | B10: Functional Area 8 | C10: Protect responders and ensure welfare, fatigue management, inclusion and safe emergency operations. | D10: MOO Functional Area 8; A2, A7, B4 | E10: A2.7; A7.6; B4.3–B4.6 | F10: Insurance/PPE/MHPSS records, inclusion plans, sector representatives' confirmation, rosters, welfare procedures | G10: Responder safety and inclusion findings | H10: Ch.2/4; EOC Ch.5 | I10: Duty/welfare alerts; protected role data; inclusion checklist | J10: responder_profiles; welfare_records; duty_rosters; inclusion_controls | K10: Life-safety and duty-of-care gaps | L10: Critical
A11: MR-10 | B11: Functional Area 9 | C11: Ensure digital continuity, cybersecurity, alternate EOC capability, backup power/connectivity and protected data. | D11: MOO Functional Area 9; A3.4, A5.5, B2, B3 | E11: A3.4; A5.5; B2.1–B2.7; B3.3–B3.6 | F11: PSCP, site assessment, generator/failover tests, privacy/security records | G11: Continuity/cyber resilience baseline | H11: EOC Ch.3–4; EOC Ch.7 | I11: Continuity status; test history; incident/audit logs | J11: facilities; alternate_eoc; backups; cybersecurity_controls; continuity_plans | K11: High/critical for single points of failure | L11: Critical
A12: MR-11 | B12: Functional Area 10 | C12: Institutionalize recovery, learning, M&E, AARs, improvement tracking and annual reassessment. | D12: MOO Functional Area 10; A9, A10, B7 | E12: A9.1–A9.5; A10.4–A10.9; B7.3–B7.6 | F12: Recovery plans and pre-disaster recovery framework, AARs, M&E reports, recognition results, exercise records, learning exchanges | G12: Recovery and continuous-improvement findings | H12: Ch.7–8; EOC Ch.8–9 | I12: Improvement cycle; annual reassessment; change history | J12: recovery_plans; aar_records; lessons_learned; improvement_actions; assessment_cycles; learning_exchanges | K12: Trend and closure tracking | L12: High
... A19: MR-18 | B19: Framework alignment: UNDRR Disaster Resilience Scorecard | C19: Keep each Scorecard-derived indicator traceable to its DRSC criterion so results can feed MCR2030 and Sendai reporting; Scorecard criteria not adopted stay for a city-wide Scorecard workshop and are not scored. | D19: UNDRR DRSC Detailed Level Assessment (2017); IAT v1.1 Crosswalk | E19: A2.10; A4.9; A5.7; A5.8; A5.9; A7.6; A7.8; A7.9; A9.5; A10.2; A10.9; B5.7; B6.6; C1.1; C1.2; C1.3; C1.4; C2.1; C2.2; C2.3; C3.1; C3.2; C5.1 | F19: DRSC reference in each indicator; Framework_Crosswalk sheet | G19: §2 Background and method; Crosswalk annex | H19: MOO Ch.7 M&E and reporting | I19: Framework crosswalk view; external framework tags on indicators | J19: framework_refs; indicator_framework_links | K19: Deferred criteria are not scored | L19: Medium

Sheet Domain_Traceability
A1: Domain Code | B1: Part | C1: Domain | D1: Indicators | E1: Mandatory | F1: Good Practice | G1: Primary Functional Area | H1: Platform Module | I1: Situational Analysis Section | J1: MOO Chapter/Area | K1: Core Platform Entities | L1: Primary Digital Workflow | M1: Report / Decision Use | N1: Index | O1: Added in v1.1
A2: A1 | B2: A | C2: Legal Mandate & DRRM Governance | D2: =COUNTIF(Indicator_Data_Dictionary!$C$2:$C$141,A2) -> 8 | E2: =COUNTIFS(Indicator_Data_Dictionary!$C$2:$C$141,A2,Indicator_Data_Dictionary!$G$2:$G$141,"M") -> 6 | F2: =COUNTIFS(Indicator_Data_Dictionary!$C$2:$C$141,A2,Indicator_Data_Dictionary!$G$2:$G$141,"GP") -> 2 | G2: 1 Governance, Organization & Institutional Arrangements | H2: Governance & Institutional Management | I2: 3. Results for Part A (CDRRMO), by domain; 5. Readiness under RA 12287 (selected indicators) | J2: MOO Ch.1; MOO Ch.1 / EOC Ch.2; MOO Ch.1 Legal & Institutional Framework; MOO Ch.2 Office Organization | K2: organizations; legal_instruments; governance_bodies; policies; declarations | L2: Governance baseline → gap → institutional action; declaration-readiness check | M2: Score → evidence → gap → priority → action → MOO | N2: Institutional Maturity Index | O2: =COUNTIFS(Indicator_Data_Dictionary!$C$2:$C$141,A2,Indicator_Data_Dictionary!$Y$2:$Y$141,"Added*") -> 1
A3: A2 | B3: A | C3: Organization, Staffing & Human Resources | D3: =COUNTIF(Indicator_Data_Dictionary!$C$2:$C$141,A3) -> 10 | E3: =COUNTIFS(Indicator_Data_Dictionary!$C$2:$C$141,A3,Indicator_Data_Dictionary!$G$2:$G$141,"M") -> 7 | F3: =COUNTIFS(Indicator_Data_Dictionary!$C$2:$C$141,A3,Indicator_Data_Dictionary!$G$2:$G$141,"GP") -> 3 | G3: 1 Governance, Organization & Institutional Arrangements | H3: Governance & Institutional Management | I3: 3. Results for Part A (CDRRMO), by domain; 5. Readiness under RA 12287 (selected indicators) | J3: MOO Ch.2; MOO Ch.2 / Annex JDs; MOO Ch.2 / Ch.4; MOO Ch.2 / Ch.6; MOO Ch.2 Office Organization; MOO Ch.4 Operations / EOC Ch.4; MOO Ch.6; MOO Ch.6 Capacity Development | K3: organizations; offices; positions; staff_assignments; duty_rosters; training_records; skills_inventory; aa_focal_points | L3: Staffing/roster baseline → capacity action | M3: Score → evidence → gap → priority → action → MOO | N3: Institutional Maturity Index | O3: =COUNTIFS(Indicator_Data_Dictionary!$C$2:$C$141,A3,Indicator_Data_Dictionary!$Y$2:$Y$141,"Added*") -> 2
A4: A3 | B4: A | C4: DRRM & Contingency Planning | D4: =COUNTIF(Indicator_Data_Dictionary!$C$2:$C$141,A4) -> 7 | E4: =COUNTIFS(Indicator_Data_Dictionary!$C$2:$C$141,A4,Indicator_Data_Dictionary!$G$2:$G$141,"M") -> 6 | F4: =COUNTIFS(Indicator_Data_Dictionary!$C$2:$C$141,A4,Indicator_Data_Dictionary!$G$2:$G$141,"GP") -> 1 | G4: 3 Preparedness, Planning & Capacity Development | H4: Preparedness & Capacity | I4: 3. Results for Part A (CDRRMO), by domain | J4: MOO Ch.3; MOO Ch.3 / EOC Ch.3; MOO Ch.3 / EOC Ch.7; MOO Ch.3 Planning; MOO Ch.4 / EOC Ch.3; MOO Ch.5 Financing | K4: plans; contingency_plans; continuity_plans; evacuation_plans | L4: Plan review → preparedness/continuity action | M4: Score → evidence → gap → priority → action → MOO | N4: Institutional Maturity Index | O4: =COUNTIFS(Indicator_Data_Dictionary!$C$2:$C$141,A4,Indicator_Data_Dictionary!$Y$2:$Y$141,"Added*") -> 0
A5: A4 | B5: A | C5: DRRM Financing & Fund Management | D5: =COUNTIF(Indicator_Data_Dictionary!$C$2:$C$141,A5) -> 9 | E5: =COUNTIFS(Indicator_Data_Dictionary!$C$2:$C$141,A5,Indicator_Data_Dictionary!$G$2:$G$141,"M") -> 6 | F5: =COUNTIFS(Indicator_Data_Dictionary!$C$2:$C$141,A5,Indicator_Data_Dictionary!$G$2:$G$141,"GP") -> 3 | G5: 1 Governance, Organization & Institutional Arrangements | H5: Governance & Institutional Management | I5: 3. Results for Part A (CDRRMO), by domain; 5. Readiness under RA 12287 (selected indicators) | J5: MOO Ch.5; MOO Ch.5 / EOC Ch.6; MOO Ch.5 Financing | K5: budgets; ldrmmf_allocations; fund_transactions; procurement_records; aa_fund_allocations; scenario_costings | L5: Finance review → funding/procurement action | M5: Score → evidence → gap → priority → action → MOO | N5: Institutional Maturity Index | O5: =COUNTIFS(Indicator_Data_Dictionary!$C$2:$C$141,A5,Indicator_Data_Dictionary!$Y$2:$Y$141,"Added*") -> 1
A6: A5 | B6: A | C6: Risk Assessment, Data & Knowledge Management | D6: =COUNTIF(Indicator_Data_Dictionary!$C$2:$C$141,A6) -> 9 | E6: =COUNTIFS(Indicator_Data_Dictionary!$C$2:$C$141,A6,Indicator_Data_Dictionary!$G$2:$G$141,"M") -> 4 | F6: =COUNTIFS(Indicator_Data_Dictionary!$C$2:$C$141,A6,Indicator_Data_Dictionary!$G$2:$G$141,"GP") -> 5 | G6: 2 Risk Intelligence, Prevention & Mitigation | H6: Risk Intelligence & GIS | I6: 3. Results for Part A (CDRRMO), by domain | J6: MOO Ch.3; MOO Ch.3 / EOC Ch.3; MOO Ch.3 / EOC Ch.5; MOO Ch.7; MOO Ch.7 Knowledge Mgmt | K6: hazards; risk_scenarios; exposure_assets; gis_layers; datasets; privacy_controls; critical_facilities; facility_dependencies; dataset_versions; shared_repository | L6: Risk/data review → GIS/data action | M6: Score → evidence → gap → priority → action → MOO | N6: Institutional Maturity Index | O6: =COUNTIFS(Indicator_Data_Dictionary!$C$2:$C$141,A6,Indicator_Data_Dictionary!$Y$2:$Y$141,"Added*") -> 3
A7: A6 | B7: A | C7: Early Warning & Risk Communication | D7: =COUNTIF(Indicator_Data_Dictionary!$C$2:$C$141,A7) -> 7 | E7: =COUNTIFS(Indicator_Data_Dictionary!$C$2:$C$141,A7,Indicator_Data_Dictionary!$G$2:$G$141,"M") -> 4 | F7: =COUNTIFS(Indicator_Data_Dictionary!$C$2:$C$141,A7,Indicator_Data_Dictionary!$G$2:$G$141,"GP") -> 3 | G7: 5 Early Warning, Emergency Communications & Public Information | H7: Early Warning & Public Information | I7: 3. Results for Part A (CDRRMO), by domain; 5. Readiness under RA 12287 (selected indicators) | J7: EOC Ch.2 Concept of Operations; EOC Ch.5; MOO Ch.4; MOO Ch.4 / EOC Ch.3; MOO Ch.4 / EOC Ch.5; MOO Ch.6 | K7: warning_systems; thresholds; warning_messages; dissemination_events; channels; advisory_templates | L7: Warning chain test → warning improvement | M7: Score → evidence → gap → priority → action → MOO | N7: Institutional Maturity Index | O7: =COUNTIFS(Indicator_Data_Dictionary!$C$2:$C$141,A7,Indicator_Data_Dictionary!$Y$2:$Y$141,"Added*") -> 1
A8: A7 | B8: A | C8: Preparedness & Community Capacity | D8: =COUNTIF(Indicator_Data_Dictionary!$C$2:$C$141,A8) -> 9 | E8: =COUNTIFS(Indicator_Data_Dictionary!$C$2:$C$141,A8,Indicator_Data_Dictionary!$G$2:$G$141,"M") -> 5 | F8: =COUNTIFS(Indicator_Data_Dictionary!$C$2:$C$141,A8,Indicator_Data_Dictionary!$G$2:$G$141,"GP") -> 4 | G8: 3 Preparedness, Planning & Capacity Development | H8: Preparedness & Capacity | I8: 3. Results for Part A (CDRRMO), by domain | J8: EOC Ch.6 Logistics; MOO Ch.3 / Ch.4; MOO Ch.4 / EOC Ch.6; MOO Ch.6; MOO Ch.6 Capacity Development | K8: training; exercises; barangay_profiles; evacuation_centers; stock_inventories; welfare_checks; refresher_schedules | L8: Readiness/drill/EC review → capacity action | M8: Score → evidence → gap → priority → action → MOO | N8: Institutional Maturity Index | O8: =COUNTIFS(Indicator_Data_Dictionary!$C$2:$C$141,A8,Indicator_Data_Dictionary!$Y$2:$Y$141,"Added*") -> 2
A9: A8 | B9: A | C9: Response Capability | D9: =COUNTIF(Indicator_Data_Dictionary!$C$2:$C$141,A9) -> 9 | E9: =COUNTIFS(Indicator_Data_Dictionary!$C$2:$C$141,A9,Indicator_Data_Dictionary!$G$2:$G$141,"M") -> 8 | F9: =COUNTIFS(Indicator_Data_Dictionary!$C$2:$C$141,A9,Indicator_Data_Dictionary!$G$2:$G$141,"GP") -> 1 | G9: 4 EOC Activation, Incident Management & Coordination | H9: Incident Management & Response | I9: 3. Results for Part A (CDRRMO), by domain; 5. Readiness under RA 12287 (selected indicators) | J9: EOC Ch.2; EOC Ch.2 / MOO Ch.4; EOC Ch.4; MOO Ch.4; MOO Ch.4 / EOC Ch.6; MOO Ch.4 Response Operations | K9: incident_types; imt_rosters; response_teams; resources; pdras; rdana_mdm; aa_protocols; prepositioning_orders; beneficiary_targeting | L9: ICS/response readiness → response action; AA protocol → prepositioning order | M9: Score → evidence → gap → priority → action → MOO | N9: Institutional Maturity Index | O9: =COUNTIFS(Indicator_Data_Dictionary!$C$2:$C$141,A9,Indicator_Data_Dictionary!$Y$2:$Y$141,"Added*") -> 2
A10: A9 | B10: A | C10: Rehabilitation & Recovery | D10: =COUNTIF(Indicator_Data_Dictionary!$C$2:$C$141,A10) -> 5 | E10: =COUNTIFS(Indicator_Data_Dictionary!$C$2:$C$141,A10,Indicator_Data_Dictionary!$G$2:$G$141,"M") -> 1 | F10: =COUNTIFS(Indicator_Data_Dictionary!$C$2:$C$141,A10,Indicator_Data_Dictionary!$G$2:$G$141,"GP") -> 4 | G10: 10 Recovery, Learning, Performance & Continuous Improvement | H10: Recovery & Continuous Improvement | I10: 3. Results for Part A (CDRRMO), by domain | J10: MOO Ch.8; MOO Ch.8 Recovery | K10: recovery_assessments; recovery_plans; recovery_actions; service_referrals; recovery_frameworks | L10: Recovery readiness → recovery action | M10: Score → evidence → gap → priority → action → MOO | N10: Institutional Maturity Index | O10: =COUNTIFS(Indicator_Data_Dictionary!$C$2:$C$141,A10,Indicator_Data_Dictionary!$Y$2:$Y$141,"Added*") -> 1
A11: A10 | B11: A | C11: Partnerships, M&E & Accountability | D11: =COUNTIF(Indicator_Data_Dictionary!$C$2:$C$141,A11) -> 9 | E11: =COUNTIFS(Indicator_Data_Dictionary!$C$2:$C$141,A11,Indicator_Data_Dictionary!$G$2:$G$141,"M") -> 4 | F11: =COUNTIFS(Indicator_Data_Dictionary!$C$2:$C$141,A11,Indicator_Data_Dictionary!$G$2:$G$141,"GP") -> 5 | G11: 1 Governance, Organization & Institutional Arrangements | H11: Governance, Partnerships & Performance | I11: 3. Results for Part A (CDRRMO), by domain; 5. Readiness under RA 12287 (selected indicators) | J11: MOO Ch.5; MOO Ch.7; MOO Ch.7 / EOC Ch.5; MOO Ch.9; MOO Ch.9 Partnerships / EOC Ch.6 | K11: partnerships; reports; performance_reviews; aar_records; lessons_learned; declaration_reports; learning_exchanges | L11: Partnership/M&E/AAR → improvement action | M11: Score → evidence → gap → priority → action → MOO | N11: Institutional Maturity Index | O11: =COUNTIFS(Indicator_Data_Dictionary!$C$2:$C$141,A11,Indicator_Data_Dictionary!$Y$2:$Y$141,"Added*") -> 2
A12: B1 | B12: B | C12: EOC Legal Basis & Concept of Operations | D12: =COUNTIF(Indicator_Data_Dictionary!$C$2:$C$141,A12) -> 5 | E12: =COUNTIFS(Indicator_Data_Dictionary!$C$2:$C$141,A12,Indicator_Data_Dictionary!$G$2:$G$141,"M") -> 5 | F12: =COUNTIFS(Indicator_Data_Dictionary!$C$2:$C$141,A12,Indicator_Data_Dictionary!$G$2:$G$141,"GP") -> 0 | G12: 4 EOC Activation, Incident Management & Coordination | H12: EOC Activation & Incident Management | I12: 4. Results for Part B (EOC), by domain | J12: EOC Ch.1 Legal Basis; EOC Ch.2; EOC Ch.2 Concept of Operations | K12: eoc_configurations; activation_levels; activation_events; authorities; declarations | L12: Activation drill → EOC activation action | M12: Score → evidence → gap → priority → action → MOO | N12: Institutional Maturity Index | O12: =COUNTIFS(Indicator_Data_Dictionary!$C$2:$C$141,A12,Indicator_Data_Dictionary!$Y$2:$Y$141,"Added*") -> 0
A13: B2 | B13: B | C13: EOC Facility, Site & Resilience | D13: =COUNTIF(Indicator_Data_Dictionary!$C$2:$C$141,A13) -> 7 | E13: =COUNTIFS(Indicator_Data_Dictionary!$C$2:$C$141,A13,Indicator_Data_Dictionary!$G$2:$G$141,"M") -> 4 | F13: =COUNTIFS(Indicator_Data_Dictionary!$C$2:$C$141,A13,Indicator_Data_Dictionary!$G$2:$G$141,"GP") -> 3 | G13: 9 Digital Continuity, Cybersecurity & Systems Resilience | H13: EOC Facility & Continuity | I13: 4. Results for Part B (EOC), by domain | J13: EOC Ch.3; EOC Ch.3 / Ch.7; EOC Ch.3 Facility | K13: facilities; sites; resilience_assets; generators; alternate_eoc | L13: Facility inspection/test → continuity action | M13: Score → evidence → gap → priority → action → MOO | N13: Institutional Maturity Index | O13: =COUNTIFS(Indicator_Data_Dictionary!$C$2:$C$141,A13,Indicator_Data_Dictionary!$Y$2:$Y$141,"Added*") -> 0
... A23: C5 | B23: C | C23: Interface: Economic Continuity | D23: =COUNTIF(Indicator_Data_Dictionary!$C$2:$C$141,A23) -> 1 | E23: =COUNTIFS(Indicator_Data_Dictionary!$C$2:$C$141,A23,Indicator_Data_Dictionary!$G$2:$G$141,"M") -> 0 | F23: =COUNTIFS(Indicator_Data_Dictionary!$C$2:$C$141,A23,Indicator_Data_Dictionary!$G$2:$G$141,"GP") -> 1 | G23: 3 Preparedness, Planning & Capacity Development | H23: Interface & Sector Coordination (Part C) | I23: 6. Results for Part C (interface), by lead office | J23: MOO Ch.9 | K23: interface_offices; business_outreach; partners; outreach_materials | L23: Outreach record review → partnership action | M23: Score → evidence → gap → lead office → inter-office action → MOO (separate Interface Index) | N23: Interface Index (separate) | O23: =COUNTIFS(Indicator_Data_Dictionary!$C$2:$C$141,A23,Indicator_Data_Dictionary!$Y$2:$Y$141,"Added*") -> 1
A24: TOTAL | C24: Parts A–C | D24: =SUM(D2:D23) -> 140 | E24: =SUM(E2:E23) -> 79 | F24: =SUM(F2:F23) -> 61 | O24: =SUM(O2:O23) -> 32

Sheet Indicator_Data_Dictionary
A1: Indicator ID | B1: Part | C1: Domain Code | D1: Domain | E1: Indicator Statement | F1: Standard / Reference | G1: Type | H1: Weight | I1: Means of Verification | J1: Source MOO Chapter | K1: Primary Functional Area | L1: Proposed Field Methods* | M1: Evidence / Scoring Gate | N1: Situational Analysis Use | O1: Draft MOO Requirement Type* | P1: Digital Platform Module | Q1: Core Data Entities* | R1: Digital Workflow / Feature* | S1: Priority Formula | T1: Annual Reassessment | U1: Lead Office (Part C) | V1: Index Inclusion | W1: Thematic Tags* | X1: Master Requirement(s)* | Y1: Version Status (v1.1)
A2: A1.1 | B2: A | C2: A1 | D2: Legal Mandate & DRRM Governance | E2: City ordinance/EO creating the CDRRMO as a regular office (not ad hoc), with defined functions mirroring RA 10121 Sec. 12(c) | F2: RA 10121 Sec. 12; IRR Rule 6; JMC 2014-1 | G2: M | H2: 3 | I2: Ordinance/EO; Sangguniang Panlungsod records | J2: MOO Ch.1 Legal & Institutional Framework | K2: 1 Governance, Organization & Institutional Arrangements | L2: DR + KII + OBS/TST as applicable | M2: Score capped by strongest evidence; Approved document AND proof of use; interviews/FGDs alone cannot support score 3. | N2: Domain result: score + evidence + gap + priority; §3 Part A CDRRMO results; §7 Mandatory Compliance Summary; §9 Action Plan; §10 MOO implications | O2: Governance / operational standard | P2: Governance & Institutional Management | Q2: organizations; legal_instruments; governance_bodies; policies; declarations | R2: Assessment response → evidence → validation → score → gap → priority → action → MOO traceability | S2: (4-score) × weight × 1.5 (Mandatory) | T2: Retain cycle history; compare year-over-year | U2: — | V2: Institutional Maturity Index (A+B) | W2: — | X2: MR-02; MR-01; MR-12–MR-15 | Y2: Unchanged
A3: A1.2 | B3: A | C3: A1 | D3: Legal Mandate & DRRM Governance | E3: CDRRMC constituted with complete membership per RA 10121 Sec. 11 (incl. CSO and private sector reps) | F3: RA 10121 Sec. 11 | G3: M | H3: 2 | I3: EO on CDRRMC composition; list of members | J3: MOO Ch.1 | K3: 1 Governance, Organization & Institutional Arrangements | L3: DR + KII | M3: Score capped by strongest evidence; Approved document AND proof of use; interviews/FGDs alone cannot support score 3. | N3: Domain result: score + evidence + gap + priority; §3 Part A CDRRMO results; §7 Mandatory Compliance Summary; §9 Action Plan; §10 MOO implications | O3: Governance / operational standard | P3: Governance & Institutional Management | Q3: organizations; legal_instruments; governance_bodies; policies; declarations | R3: Assessment response → evidence → validation → score → gap → priority → action → MOO traceability | S3: (4-score) × weight × 1.5 (Mandatory) | T3: Retain cycle history; compare year-over-year | U3: — | V3: Institutional Maturity Index (A+B) | W3: — | X3: MR-02; MR-01; MR-12–MR-15 | Y3: Unchanged
A4: A1.3 | B4: A | C4: A1 | D4: Legal Mandate & DRRM Governance | E4: CDRRMC meets at least quarterly (and as needed); minutes and resolutions on file | F4: RA 10121 Sec. 11; GKS/SGLG functionality criteria | G4: M | H4: 2 | I4: Minutes, attendance, resolutions (last 4 quarters) | J4: MOO Ch.1 | K4: 1 Governance, Organization & Institutional Arrangements | L4: DR + KII | M4: Score capped by strongest evidence; Approved document AND proof of use; interviews/FGDs alone cannot support score 3. | N4: Domain result: score + evidence + gap + priority; §3 Part A CDRRMO results; §7 Mandatory Compliance Summary; §9 Action Plan; §10 MOO implications | O4: Governance / operational standard | P4: Governance & Institutional Management | Q4: organizations; legal_instruments; governance_bodies; policies; declarations | R4: Assessment response → evidence → validation → score → gap → priority → action → MOO traceability | S4: (4-score) × weight × 1.5 (Mandatory) | T4: Retain cycle history; compare year-over-year | U4: — | V4: Institutional Maturity Index (A+B) | W4: — | X4: MR-02; MR-01; MR-12–MR-15 | Y4: Unchanged
A5: A1.4 | B5: A | C5: A1 | D5: Legal Mandate & DRRM Governance | E5: CDRRMO serves as CDRRMC secretariat with documented secretariat procedures | F5: RA 10121 Sec. 12(c)(17) | G5: M | H5: 1 | I5: Secretariat SOP; agenda/minutes templates | J5: MOO Ch.2 Office Organization | K5: 1 Governance, Organization & Institutional Arrangements | L5: DR + KII | M5: Score capped by strongest evidence; Approved document AND proof of use; interviews/FGDs alone cannot support score 3. | N5: Domain result: score + evidence + gap + priority; §3 Part A CDRRMO results; §7 Mandatory Compliance Summary; §9 Action Plan; §10 MOO implications | O5: SOP / protocol | P5: Governance & Institutional Management | Q5: organizations; legal_instruments; governance_bodies; policies; declarations | R5: Assessment response → evidence → validation → score → gap → priority → action → MOO traceability | S5: (4-score) × weight × 1.5 (Mandatory) | T5: Retain cycle history; compare year-over-year | U5: — | V5: Institutional Maturity Index (A+B) | W5: — | X5: MR-02; MR-01; MR-12–MR-15 | Y5: Unchanged
A6: A1.5 | B6: A | C6: A1 | D6: Legal Mandate & DRRM Governance | E6: Local DRRM-related ordinances in force (e.g., pre-emptive/forced evacuation, no-build zones, hazard-based zoning) | F6: RA 10121 Sec. 12(c)(19); RA 7160; CLUP/ZO | G6: GP | H6: 2 | I6: Ordinances; ZO; enforcement records | J6: MOO Ch.1 | K6: 1 Governance, Organization & Institutional Arrangements | L6: DR + KII | M6: Score capped by strongest evidence; Approved document AND proof of use; interviews/FGDs alone cannot support score 3. | N6: Domain result: score + evidence + gap + priority; §3 Part A CDRRMO results; §8 Strengths / Good Practices; §9 Action Plan; §10 MOO implications | O6: Governance / operational standard | P6: Governance & Institutional Management | Q6: organizations; legal_instruments; governance_bodies; policies; declarations | R6: Assessment response → evidence → validation → score → gap → priority → action → MOO traceability | S6: (4-score) × weight × 1.0 (Good Practice) | T6: Retain cycle history; compare year-over-year | U6: — | V6: Institutional Maturity Index (A+B) | W6: — | X6: MR-02; MR-01; MR-12–MR-15 | Y6: Unchanged
A7: A1.6 | B7: A | C7: A1 | D7: Legal Mandate & DRRM Governance | E7: Protocol for declaring a State of Calamity, incl. CDRRMC recommendation steps and post-declaration measures (State of Imminent Disaster now assessed separately under A1.8) | F7: RA 10121 Sec. 16 | G7: M | H7: 3 | I7: Protocol/SOP; past CDRRMC resolutions | J7: MOO Ch.1 | K7: 1 Governance, Organization & Institutional Arrangements | L7: DR + KII + OBS/TST as applicable | M7: Score capped by strongest evidence; Approved document AND proof of use; interviews/FGDs alone cannot support score 3. | N7: Domain result: score + evidence + gap + priority; §3 Part A CDRRMO results; §7 Mandatory Compliance Summary; §9 Action Plan; §10 MOO implications | O7: SOP / protocol | P7: Governance & Institutional Management | Q7: organizations; legal_instruments; governance_bodies; policies; declarations | R7: Assessment response → evidence → validation → score → gap → priority → action → MOO traceability | S7: (4-score) × weight × 1.5 (Mandatory) | T7: Retain cycle history; compare year-over-year | U7: — | V7: Institutional Maturity Index (A+B) | W7: — | X7: MR-02; MR-01; MR-12–MR-15 | Y7: Revised in v1.1
A8: A1.7 | B8: A | C8: A1 | D8: Legal Mandate & DRRM Governance | E8: DRRM is represented in City Development Council and Local Finance Committee deliberations | F8: RA 7160; JMC 2013-1 | G8: GP | H8: 1 | I8: Minutes; LDC/LFC membership | J8: MOO Ch.1 | K8: 1 Governance, Organization & Institutional Arrangements | L8: DR + KII | M8: Score capped by strongest evidence; Approved document AND proof of use; interviews/FGDs alone cannot support score 3. | N8: Domain result: score + evidence + gap + priority; §3 Part A CDRRMO results; §8 Strengths / Good Practices; §9 Action Plan; §10 MOO implications | O8: Governance / operational standard | P8: Governance & Institutional Management | Q8: organizations; legal_instruments; governance_bodies; policies; declarations | R8: Assessment response → evidence → validation → score → gap → priority → action → MOO traceability | S8: (4-score) × weight × 1.0 (Good Practice) | T8: Retain cycle history; compare year-over-year | U8: — | V8: Institutional Maturity Index (A+B) | W8: — | X8: MR-02; MR-01; MR-12–MR-15 | Y8: Unchanged
A9: A1.8 | B9: A | C9: A1 | D9: Legal Mandate & DRRM Governance | E9: State of Imminent Disaster procedure: CDRRMC coordinates with RDRRMC VIII when the pre-disaster risk assessment shows reasonable certainty of severe impact; request format to RDRRMC (24-hour reply); Mayor's EO template; adoption rule when the Region (or Province, applicability to an ICC to be confirmed) is declared; lifting grounds and authority | F9: RA 12287; RA 12287 IRR (2026) Rule II Sec. 6; Rule III Secs. 2-4 | G9: M | H9: 3 | I9: SOP; EO template; CDRRMC resolution and RDRRMC request templates | J9: MOO Ch.1 / EOC Ch.2 | K9: 1 Governance, Organization & Institutional Arrangements | L9: DR + KII | M9: Score capped by strongest evidence; Approved document AND proof of use; interviews/FGDs alone cannot support score 3. | N9: Domain result: score + evidence + gap + priority; §3 Part A CDRRMO results; §5 Readiness under RA 12287; §7 Mandatory Compliance Summary; §9 Action Plan; §10 MOO implications | O9: SOP / protocol | P9: Governance & Institutional Management | Q9: organizations; legal_instruments; governance_bodies; policies; declarations | R9: Assessment response → evidence → validation → score → gap → priority → action → MOO traceability | S9: (4-score) × weight × 1.5 (Mandatory) | T9: Retain cycle history; compare year-over-year | U9: — | V9: Institutional Maturity Index (A+B) | W9: RA 12287 / anticipatory action | X9: MR-02; MR-05; MR-16; MR-01; MR-12–MR-15 | Y9: Added in v1.1
A10: A2.1 | B10: A | C10: A2 | D10: Organization, Staffing & Human Resources | E10: Organizational structure follows JMC 2014-1: Head + Administration & Training, Research & Planning, and Operations & Warning divisions | F10: NDRRMC-DILG-DBM-CSC JMC 2014-1 | G10: M | H10: 3 | I10: Approved organogram; plantilla | J10: MOO Ch.2 Office Organization | K10: 1 Governance, Organization & Institutional Arrangements | L10: DR + KII + OBS/TST as applicable | M10: Score capped by strongest evidence; Approved document AND proof of use; interviews/FGDs alone cannot support score 3. | N10: Domain result: score + evidence + gap + priority; §3 Part A CDRRMO results; §7 Mandatory Compliance Summary; §9 Action Plan; §10 MOO implications | O10: Organization / role standard | P10: Governance & Institutional Management | Q10: organizations; offices; positions; staff_assignments; duty_rosters; training_records; skills_inventory; aa_focal_points | R10: Assessment response → evidence → validation → score → gap → priority → action → MOO traceability | S10: (4-score) × weight × 1.5 (Mandatory) | T10: Retain cycle history; compare year-over-year | U10: — | V10: Institutional Maturity Index (A+B) | W10: — | X10: MR-02; MR-01; MR-12–MR-15 | Y10: Unchanged
A11: A2.2 | B11: A | C11: A2 | D11: Organization, Staffing & Human Resources | E11: CDRRMO Head is a permanent plantilla position filled by a qualified appointee | F11: RA 10121 Sec. 12(b); JMC 2014-1 | G11: M | H11: 3 | I11: Appointment; PDS vs CSC QS | J11: MOO Ch.2 | K11: 1 Governance, Organization & Institutional Arrangements | L11: DR + KII + OBS/TST as applicable | M11: Score capped by strongest evidence; Approved document AND proof of use; interviews/FGDs alone cannot support score 3. | N11: Domain result: score + evidence + gap + priority; §3 Part A CDRRMO results; §7 Mandatory Compliance Summary; §9 Action Plan; §10 MOO implications | O11: Organization / role standard | P11: Governance & Institutional Management | Q11: organizations; offices; positions; staff_assignments; duty_rosters; training_records; skills_inventory; aa_focal_points | R11: Assessment response → evidence → validation → score → gap → priority → action → MOO traceability | S11: (4-score) × weight × 1.5 (Mandatory) | T11: Retain cycle history; compare year-over-year | U11: — | V11: Institutional Maturity Index (A+B) | W11: — | X11: MR-02; MR-01; MR-12–MR-15 | Y11: Unchanged
A12: A2.3 | B12: A | C12: A2 | D12: Organization, Staffing & Human Resources | E12: Minimum plantilla positions per JMC 2014-1 created and filled (ratio of filled/required) | F12: JMC 2014-1; CSC QS | G12: M | H12: 3 | I12: Plantilla of Personnel; vacancy list | J12: MOO Ch.2 | K12: 1 Governance, Organization & Institutional Arrangements | L12: DR + KII + OBS/TST as applicable | M12: Score capped by strongest evidence; Approved document AND proof of use; interviews/FGDs alone cannot support score 3. | N12: Domain result: score + evidence + gap + priority; §3 Part A CDRRMO results; §7 Mandatory Compliance Summary; §9 Action Plan; §10 MOO implications | O12: Organization / role standard | P12: Governance & Institutional Management | Q12: organizations; offices; positions; staff_assignments; duty_rosters; training_records; skills_inventory; aa_focal_points | R12: Assessment response → evidence → validation → score → gap → priority → action → MOO traceability | S12: (4-score) × weight × 1.5 (Mandatory) | T12: Retain cycle history; compare year-over-year | U12: — | V12: Institutional Maturity Index (A+B) | W12: — | X12: MR-02; MR-01; MR-12–MR-15 | Y12: Unchanged
A13: A2.4 | B13: A | C13: A2 | D13: Organization, Staffing & Human Resources | E13: Job descriptions/position descriptions defined for every position, aligned to RA 10121 functions | F13: CSC rules; JMC 2014-1 | G13: M | H13: 2 | I13: JDs/PDFs; IPCR/OPCR | J13: MOO Ch.2 / Annex JDs | K13: 1 Governance, Organization & Institutional Arrangements | L13: DR + KII | M13: Score capped by strongest evidence; Approved document AND proof of use; interviews/FGDs alone cannot support score 3. | N13: Domain result: score + evidence + gap + priority; §3 Part A CDRRMO results; §7 Mandatory Compliance Summary; §9 Action Plan; §10 MOO implications | O13: Organization / role standard | P13: Governance & Institutional Management | Q13: organizations; offices; positions; staff_assignments; duty_rosters; training_records; skills_inventory; aa_focal_points | R13: Assessment response → evidence → validation → score → gap → priority → action → MOO traceability | S13: (4-score) × weight × 1.5 (Mandatory) | T13: Retain cycle history; compare year-over-year | U13: — | V13: Institutional Maturity Index (A+B) | W13: — | X13: MR-02; MR-01; MR-12–MR-15 | Y13: Unchanged
... A141: C5.1 | B141: C | C141: C5 | D141: Interface: Economic Continuity | E141: Business continuity outreach to local businesses based on shared hazard scenarios (outreach only; no mandate implied) | F141: UNDRR DRSC 7.3.2 | G141: GP | H141: 1 | I141: Outreach records; materials | J141: MOO Ch.9 | K141: 3 Preparedness, Planning & Capacity Development | L141: DR + KII | M141: Score capped by strongest evidence; Approved document AND proof of use; interviews/FGDs alone cannot support score 3. Evidence is supplied by the lead office. | N141: Domain result: score + evidence + gap + priority; §6 Part C interface results (by lead office); §9 Action Plan; §10 MOO implications | O141: Interface / coordination arrangement | P141: Interface & Sector Coordination (Part C) | Q141: interface_offices; business_outreach; partners; outreach_materials | R141: Assessment response → evidence → validation → score → gap → priority → action → MOO traceability | S141: (4-score) × weight × 1.0 (Interface; Good Practice factor) | T141: Retain cycle history; compare year-over-year; re-confirm lead office each cycle | U141: CDRRMO with Chamber of Commerce | V141: Part C Interface Index (separate) | W141: UNDRR Scorecard; Interface | X141: MR-04; MR-17; MR-18; MR-01; MR-12–MR-15 | Y141: Added in v1.1 (Part C interface)

Sheet Scoring_Lookups
A1: Score | B1: Level | C1: Description | D1: Minimum Evidence
A2: 0 | B2: Absent | C2: Not in place, and no plan to establish it. | D2: None
A3: 1 | B3: Initial / Ad hoc | C3: Done informally; depends on individuals; not documented. | D3: Verbal account only
A4: 2 | B4: Developing | C4: Exists but incomplete, outdated, unapproved or inconsistently applied. | D4: Draft/partial document or partial practice observed
A5: 3 | B5: Compliant / Established | C5: Meets legal/policy standard; documented, approved and applied. | D5: Approved document AND proof of use
A6: 4 | B6: Advanced / Institutionalized | C6: Exceeds standard; tested, reviewed and improved regularly. | D6: Level 3 evidence plus a test, exercise or AAR showing improvement
A7: NA | B7: Not applicable | C7: Does not apply to Ormoc; excluded from computation. | D7: Written justification
A9: Metric | B9: Formula / Rule
A10: Domain / Part / Institutional Maturity Index | B10: sum(score × weight) / sum(weights), scored indicators only. Institutional Maturity Index (IMI) = Parts A and B only (125 core indicators).
A11: Maturity bands | B11: <0.5 Absent; 0.5–1.49 Initial; 1.5–2.49 Developing; 2.5–3.49 Compliant; ≥3.5 Advanced
A12: Mandatory Compliance Rate | B12: Mandatory indicators scored 3 or 4 / scored Mandatory indicators
A13: Domain compliance | B13: A domain counts as compliant only at 100% Mandatory Compliance
A14: Gap Priority Score | B14: (4-score) × weight × 1.5 for Mandatory; ×1.0 for Good Practice and for all Part C interface indicators
A15: Priority bands | B15: High ≥9; Medium 4–8.9; Low <4
A16: Part C Interface Index | B16: Same formula as the Domain Maturity Index, over Part C indicators only; reported separately and never added to the IMI
A17: Part C priority | B17: Uses the Good Practice factor (×1.0): a Part C gap reaches High only at weight 3 and score 0 or 1
A18: Part C type | B18: Part C has no Mandatory indicators; the IAT Type column names the lead office instead
A20: * Design-extension fields | B20: Fields marked with * are added to make the dictionary directly usable by the Situational Analysis Report, MOO requirements engineering and future platform; they are not claimed to be verbatim fields from Annex A.

Sheet Framework_Crosswalk
A1: CROSSWALK - UNDRR SCORECARD (DETAILED LEVEL) AND RA 12287 IRR TO THE IAT v1.1
A2: Treatment: New = added indicator; Modified = existing indicator widened; Covered = already assessed; Interface = Part C; Deferred = left to the city-wide Scorecard workshop (owned by other offices or needs data the CDRRMO does not hold).
A4: A. UNDRR Disaster Resilience Scorecard for Cities - Detailed Level
A5: DRSC ref | B5: Subject | C5: Treatment | D5: IAT indicator(s) | E5: Note
A6: 1.1.1 | B6: Risk consideration in plan making | C6: Interface | D6: C1.1
A7: 1.1.2 | B7: Consultation in plan making | C7: Deferred | D7: - | E7: City planning process; Scorecard workshop
A8: 1.1.3 | B8: Review of strategic plans | C8: Covered | D8: A10.4 | E8: LDRRMP annual review
A9: 1.2.1 | B9: Pre-event planning coordination | C9: Covered | D9: A1.2, A1.3, A3.3
A10: 1.2.2 | B10: Coordination of event response | C10: Covered | D10: A8.5, B1.4, B6.1
A11: 1.2.3 | B11: City resources and authority for DRR | C11: Covered | D11: A2.3, A4.1
A12: 1.2.4 | B12: Physical contributions from partners | C12: New | D12: B6.6
A13: 1.3.1 | B13: Resilience screening of policy and budget | C13: Interface | D13: C1.2
A14: 1.4.1 | B14: Shared resilience data | C14: New | D14: A5.7
A15: 2.1.1 | B15: Knowledge of hazards | C15: Covered | D15: A5.1
A16: 2.2.1 | B16: Exposure and vulnerability scenarios | C16: Covered | D16: A5.2
A17: 2.2.2 | B17: Damage and loss estimation | C17: Interface | D17: C1.3
A18: 2.3.1 | B18: Critical assets and failure chains | C18: New | D18: A5.8
A19: 2.4.1 | B19: Hazard maps and guidelines | C19: Covered / Interface | D19: A5.1; C1.4 | E19: Maps in A5.1; development guidelines in C1.4
A20: 2.5.1 | B20: Update process | C20: New | D20: A5.9
A21: 3.1.1 | B21: Knowledge of financing options | C21: Deferred | D21: - | E21: Partly A4.7; full mapping in Scorecard workshop
A22: 3.2.1 | B22: Financial planning for resilience | C22: Covered (partial) | D22: A3.5 | E22: City-wide 5-year plan deferred
A23: 3.2.2 | B23: Capital funding | C23: Deferred | D23: - | E23: City capital program
A24: 3.2.3 | B24: Operating funding | C24: Covered / New | D24: A4.1, A4.4; A4.9
A25: 3.2.4 | B25: Contingency fund adequacy | C25: New | D25: A4.9
A26: 3.3.1 | B26: Domestic insurance coverage | C26: Deferred | D26: - | E26: Household data not available to CDRRMO
A27: 3.3.2 | B27: Non-domestic insurance coverage | C27: Covered | D27: A4.7 | E27: GSIS insurance of public assets
A28: 3.4.1-3 | B28: Incentives to businesses, non-profits, homeowners | C28: Deferred | D28: - | E28: City policy; Scorecard workshop
A29: 4.1.1-4.1.3 | B29: Population, jobs, output and farmland at risk | C29: Deferred | D29: - | E29: Needs loss modelling
A30: 4.2.1 | B30: Urban design solutions | C30: Deferred | D30: -
A31: 4.3.1 | B31: Building codes vs risk | C31: Interface (partial) | D31: C2.1 | E31: Critical facilities only
A32: 4.3.2 | B32: Updates to building codes | C32: Deferred | D32: - | E32: National code
A33: 4.3.3 | B33: Sustainable building standards | C33: Deferred | D33: -
A34: 4.4.1 | B34: Application of land use zoning | C34: Deferred | D34: - | E34: A1.5 checks ordinances exist
A35: 4.4.2 | B35: Application of building codes | C35: Interface (partial) | D35: C2.1 | E35: Critical facilities only
A36: 5.1.1 | B36: Awareness of ecosystem services | C36: Interface | D36: C3.1
A37: 5.1.2 | B37: Ecosystem health | C37: Deferred | D37: - | E37: Needs 5-year monitoring data
A38: 5.2.1 | B38: Land use impact on ecosystems | C38: Deferred | D38: -
A39: 5.2.2 | B39: Green and blue infrastructure | C39: Deferred | D39: -
A40: 5.3.1-5.3.2 | B40: Transboundary ecosystems and agreements | C40: Interface | D40: C3.2
A41: 6.1.1 | B41: Skills and experience inventory | C41: New | D41: A2.10
...

Sheet Source_Control
A1: Control Item | B1: Value
A2: Version | B2: v1.1 – October 2026 (supersedes the v1.0 dictionary of 108 indicators)
A3: Primary source | B3: Ormoc City CDRRMO & EOC Institutional Assessment Tool – Standards, Policy Basis, Assessment Framework and Methodology, v1.1 draft, October 2026; and the IAT v1.1 scoring workbook (sheets A_CDRRMO, B_EOC, C_Interface)
A4: Annex used | B4: Annex A – Indicator Catalogue (v1.1); Annex G – Assessment Report Outline (v1.1); Crosswalk sheet of the IAT workbook
A5: Additional sources applied in v1.1 | B5: IRR of RA 12287 (Declaration of State of Imminent Disaster Act), signed 14 Sep 2026; UNDRR Disaster Resilience Scorecard for Cities – Detailed Level Assessment (2017)
A6: Indicator count (all parts) | B6: =COUNTA(Indicator_Data_Dictionary!A2:A141) -> 140
A7: Part A – CDRRMO | B7: =COUNTIF(Indicator_Data_Dictionary!B2:B141,"A") -> 82
A8: Part B – EOC | B8: =COUNTIF(Indicator_Data_Dictionary!B2:B141,"B") -> 43
A9: Part C – Interface (separate index) | B9: =COUNTIF(Indicator_Data_Dictionary!B2:B141,"C") -> 15
A10: Mandatory (Parts A–B) | B10: =COUNTIF(Indicator_Data_Dictionary!G2:G141,"M") -> 79
A11: Good Practice (Parts A–B) | B11: =COUNTIFS(Indicator_Data_Dictionary!G2:G141,"GP",Indicator_Data_Dictionary!B2:B141,"<>C") -> 46
A12: Unchanged from v1.0 | B12: =COUNTIF(Indicator_Data_Dictionary!Y2:Y141,"Unchanged") -> 100
A13: Revised in v1.1 | B13: =COUNTIF(Indicator_Data_Dictionary!Y2:Y141,"Revised*") -> 8
A14: Added in v1.1 | B14: =COUNTIF(Indicator_Data_Dictionary!Y2:Y141,"Added*") -> 32
A15: Removed in v1.1 | B15: 0
A16: Source workbook sheets referenced by methodology | B16: A_CDRRMO, B_EOC and C_Interface
A17: Project use | B17: Institutional baseline → Situational Analysis Report → Draft MOO → future Digital Institutional Assessment Platform
A18: Important validation status | B18: The IAT is a draft for validation. Confirm before fieldwork: IRR effectivity date (publication and ONAR filing); NDRRMC operational guidelines on AA triggers and thresholds (pending); DBM–COA AA funding guidelines (pending); NDRRMC AA M&E framework (due about mid-Dec 2026); exact NDRRMC EOC circular number with OCD VIII.
A19: Design-extension note | B19: Fields marked * are implementation/requirements-engineering extensions, not verbatim source fields. In v1.1 five v1.0 requirement-type labels were corrected (see Change_Log).
A20: Colour key | B20: Green = added in v1.1; yellow = revised in v1.1

Sheet Change_Log
A1: Item | B1: Change | C1: Field(s) | D1: v1.0 value | E1: v1.1 value | F1: Reason / basis
A2: A1.6 | B2: Revised (IAT v1.1) | C2: Indicator Statement, Standard / Reference, Means of Verification, Source MOO Chapter | D2: Indicator Statement: Protocols for declaring State of Calamity and State of Imminent Disaster, incl. CDRRMC recommendation steps | Standard / Reference: RA 10121 Sec. 16; RA 12287 (2025) | Means of Verification: Protocol/SOP; past resolutions | Source MOO Chapter: MOO Ch.1 / EOC Manual Ch.2 | E2: Indicator Statement: Protocol for declaring a State of Calamity, incl. CDRRMC recommendation steps and post-declaration measures (State of Imminent Disaster now assessed separately under A1.8) | Standard / Reference: RA 10121 Sec. 16 | Means of Verification: Protocol/SOP; past CDRRMC resolutions | Source MOO Chapter: MOO Ch.1 | F2: Applies IRR of RA 12287 and/or UNDRR Scorecard per IAT v1.1
A3: A1.8 | B3: Added (IAT v1.1) | C3: All fields | D3: — | E3: State of Imminent Disaster procedure: CDRRMC coordinates with RDRRMC VIII when the pre-disaster risk assessment shows reasonable certainty of severe impact; request format to RDRRMC (24-hour reply); Mayor's EO template; adoption rule when the Region (or Province, applicability to an ICC to be confirmed) is declared; lifting grounds and authority | F3: RA 12287 / anticipatory action
A4: A2.1 | B4: Corrected (dictionary field) | C4: Draft MOO Requirement Type* | D4: Training / exercise standard | E4: Organization / role standard | F4: v1.0 label did not match the indicator subject
A5: A2.8 | B5: Revised (IAT v1.1) | C5: Indicator Statement, Standard / Reference | D5: Indicator Statement: Volunteer/auxiliary responder management system (accreditation, registry, deployment, insurance) | Standard / Reference: RA 10121 Sec. 13; NDRRMC volunteer guidelines | E5: Indicator Statement: Volunteer/auxiliary responder management system (accreditation, registry, deployment, insurance), incl. mobilization of ACDVs for anticipatory action | Standard / Reference: RA 10121 Sec. 13; NDRRMC volunteer guidelines; RA 12287 IRR (2026) Rule IV Sec. 5 | F5: Applies IRR of RA 12287 and/or UNDRR Scorecard per IAT v1.1
A6: A2.9 | B6: Added (IAT v1.1) | C6: All fields | D6: — | E6: Anticipatory action focal person designated in the CDRRMO, with AA training for staff, BDRRMCs, ACDVs and partner CSOs (incl. community-based early warning and early action) | F6: RA 12287 / anticipatory action
A7: A2.10 | B7: Added (IAT v1.1) | C7: All fields | D7: — | E7: Inventory of DRRM-relevant skills across the CDRRMO, partner offices and barangays (SAR, engineering, logistics, GIS, PDNA, MHPSS) updated within the last 12 months | F7: UNDRR Scorecard
A8: A4.6 | B8: Revised (IAT v1.1) | C8: Indicator Statement, Standard / Reference, Means of Verification | D8: Indicator Statement: QRF can be accessed for anticipatory/pre-disaster actions under a State of Imminent Disaster | Standard / Reference: RA 12287 (2025); RA 10121 Sec. 21 | Means of Verification: Protocol; Budget/Accounting guidance | E8: Indicator Statement: Anticipatory action funding pathway: LDRRMFIP sets an AA line within the cap of 10% of the 70% LDRRMF; other sources mapped (Special Trust Fund balances, donations, ODA); Budget, Accounting and BAC procedures allow immediate disbursement and observe the 30%/70% tranche rule around the 3-day lead time | Standard / Reference: RA 12287; RA 12287 IRR (2026) Rule V Secs. 1-3; RA 10121 Sec. 21; RA 12009 | Means of Verification: LDRRMFIP AA line; Budget/Accounting guidance; disbursement and procurement SOP | F8: Applies IRR of RA 12287 and/or UNDRR Scorecard per IAT v1.1
A9: A4.9 | B9: Added (IAT v1.1) | C9: All fields | D9: — | E9: QRF and LDRRMF adequacy tested against the most severe credible scenario (e.g., a Thelma-type flash flood or Yolanda-strength typhoon), with the shortfall and other fund sources identified | F9: UNDRR Scorecard
A10: A5.7 | B10: Added (IAT v1.1) | C10: All fields | D10: — | E10: One maintained, shared source of risk and readiness information (hazard maps, plans, contacts, readiness summary) open to CDRRMC member offices, with a public summary posted | F10: UNDRR Scorecard
A11: A5.8 | B11: Added (IAT v1.1) | C11: All fields | D11: — | E11: Critical facilities list (EOC, hospitals, evacuation centers, water, power, telecom, bridges, port) with dependencies mapped as potential failure chains and used to set protection and restoration priorities | F11: RA 12287 / anticipatory action; UNDRR Scorecard
A12: A5.9 | B12: Added (IAT v1.1) | C12: All fields | D12: — | E12: Agreed update cycle: hazard data every 3 years or less; exposure, vulnerability and critical-facility data every 18 months or less | F12: UNDRR Scorecard
... A57: Framework_Crosswalk | B57: Added | C57: Sheet | D57: — | E57: Copy of IAT v1.1 Crosswalk (Scorecard and IRR) | F57: Traceability to external frameworks
