Workbook

Sheet Guide
B2: CITY GOVERNMENT OF ORMOC
B3: Institutional Assessment Tool (IAT) for the CDRRMO and Emergency Operations Center
B4: Scoring workbook - companion to the IAT Standards, Policy & Methodology document. Version 1.1 (October 2026), draft for validation with CDRRMO Ormoc. v1.1 adds RA 12287 IRR (signed 14 Sep 2026) requirements and selected UNDRR Scorecard indicators.
B6: HOW TO USE
B7: 1. Fill in the Profile sheet (assessment date, team, informants).
B8: 2. In A_CDRRMO and B_EOC, score each indicator in the yellow 'Score' column using the 0-4 rubric below, or NA if it truly does not apply to Ormoc.
B9: 3. Record the evidence actually seen (document title/date, site observation) in 'Evidence Observed'. No evidence = score of 2 or lower.
B10: 4. Write the gap and recommended action. Priority and compliance status calculate automatically.
B11: 5. Review the Dashboard (domain maturity, mandatory compliance, priority gaps), then complete the Action_Plan sheet for High-priority items.
B12: 6. Validate scores with CDRRMO management in the validation workshop before finalizing. Change only yellow cells; grey/white cells are formulas or reference text.
B14: SCORING RUBRIC (per indicator)
B15: Score | C15: Maturity level | D15: What it looks like | E15: Minimum evidence required
B16: 0 | C16: Absent | D16: Not in place; no plan to establish. | E16: None
B17: 1 | C17: Initial / Ad hoc | D17: Done informally, depends on individuals; not documented. | E17: Verbal account (KII/FGD) only
B18: 2 | C18: Developing | D18: Exists but incomplete, outdated, unapproved or not consistently applied. | E18: Draft or partial document, or observation of partial practice
B19: 3 | C19: Compliant / Established | D19: Meets the legal/policy standard; documented, approved, applied. | E19: Approved document AND proof of use (records, logs, reports)
B20: 4 | C20: Advanced / Institutionalized | D20: Exceeds standard; tested, reviewed and improved regularly; a model for others. | E20: Level 3 evidence PLUS test/exercise/AAR showing review and improvement
B21: NA | C21: Not applicable | D21: Indicator does not apply to Ormoc's context. Excluded from computation. | E21: Written justification in Remarks
B23: AUTOMATIC CALCULATIONS
B24: Domain Maturity Index (0-4) | C24: Weighted average of scored indicators: sum(score x weight) / sum(weight). NA and blanks excluded.
B25: Maturity band | C25: <0.5 Absent | 0.5-1.49 Initial | 1.5-2.49 Developing | 2.5-3.49 Compliant | >=3.5 Advanced
B26: Mandatory Compliance Rate | C26: Share of scored Mandatory (M) indicators rated 3 or 4. Target: 100%.
B27: Gap Priority Score | C27: (4 - score) x weight x 1.5 if Mandatory (x1.0 if Good Practice). High >= 9; Medium 4-8.9; Low < 4.
B28: Weight | C28: 3 = critical to life-safety or legal compliance; 2 = important to effectiveness; 1 = supportive/good practice.
B30: CELL LEGEND
B31: Yellow | C31: Input - assessor fills in
B32: Grey | C32: Formula - do not edit
B34: EXAMPLE OF A COMPLETED ROW (illustrative only)
B35: Indicator | C35: Score | D35: Evidence Observed | E35: Gap / Remarks | F35: Recommended Action
B36: A2.6 24/7 operations capability with documented shift roster | C36: 2 | D36: Roster for Jul-Sep 2026 seen; night shift covered by 1 staff only; logbook gaps on 3 dates. | E36: Night shift below minimum; no handover form. | F36: Adopt 3-shift roster with min. 2 duty officers/shift; introduce handover form (MOO Ch.4).
B39: WHAT CHANGED IN VERSION 1.1
B40: Totals | C40: 125 indicators in Parts A and B (82 CDRRMO, 43 EOC); 79 Mandatory, 46 Good Practice. Up from 108 (73 M / 35 GP).
B41: RA 12287 IRR | C41: 6 new Mandatory indicators (A1.8, A2.9, A6.7, A8.8, A8.9, A10.8) and 6 revised (A1.6, A2.8, A4.6, A6.2, A8.6, B1.2). A4.6 now follows IRR Rule V: AA is charged to up to 10% of the 70% LDRRMF, not to the QRF.
B42: UNDRR Scorecard | C42: 11 new Good Practice indicators adapted from the Detailed Level Scorecard (A2.10, A4.9, A5.7, A5.8, A5.9, A7.8, A7.9, A9.5, A10.9, B5.7, B6.6); A7.6 and A10.2 widened. The DRSC reference sits in the Standard column.
B43: Part C | C43: New C_Interface sheet: 15 indicators owned by other offices (planning, engineering, utilities, environment, health, education, agriculture). Same rubric; separate index on the Dashboard; not counted in the IMI or the Mandatory Compliance Rate.
B44: Crosswalk | C44: The Crosswalk sheet shows how every Scorecard criterion and every IRR provision is treated: New, Modified, Covered, Interface or Deferred to the city-wide Scorecard workshop.

Sheet Dashboard
B2: INSTITUTIONAL ASSESSMENT DASHBOARD - CDRRMO & EOC, CITY OF ORMOC
B3: All values compute from the A_CDRRMO and B_EOC sheets. Maturity Index scale 0-4.
B5: Code | C5: Domain | D5: Indicators | E5: Scored | F5: Maturity Index (0-4) | G5: Maturity Band | H5: Mandatory Compliance | I5: High-priority gaps | J5: Index %
B6: A1 | C6: Legal Mandate & DRRM Governance | D6: =COUNTIF(A_CDRRMO!$B$5:$B$96,B6) -> 8 | E6: =SUMIF(A_CDRRMO!$B$5:$B$96,B6,A_CDRRMO!$S$5:$S$96) -> 8 | F6: =IF(SUMIF(A_CDRRMO!$B$5:$B$96,B6,A_CDRRMO!$R$5:$R$96)=0,"",SUMIF(A_CDRRMO!$B$5:$B$96,B6,A_CDRRMO!$Q$5:$Q$96)/SUMIF(A_CDRRMO!$B$5:$B$96,B6,A_CDRRMO!$R$5:$R$96)*4) -> 2.5882353 | G6: =IF(F6="","",IF(F6<0.5,"Absent",IF(F6<1.5,"Initial",IF(F6<2.5,"Developing",IF(F6<3.5,"Compliant","Advanced"))))) -> Compliant | H6: =IF(SUMIF(A_CDRRMO!$B$5:$B$96,B6,A_CDRRMO!$T$5:$T$96)=0,"",SUMIF(A_CDRRMO!$B$5:$B$96,B6,A_CDRRMO!$U$5:$U$96)/SUMIF(A_CDRRMO!$B$5:$B$96,B6,A_CDRRMO!$T$5:$T$96)) -> 0.5 | I6: =COUNTIFS(A_CDRRMO!$B$5:$B$96,B6,A_CDRRMO!$N$5:$N$96,"High") -> 2 | J6: =IF(F6="",0,F6/4) -> 0.64705882
B7: A2 | C7: Organization, Staffing & Human Resources | D7: =COUNTIF(A_CDRRMO!$B$5:$B$96,B7) -> 10 | E7: =SUMIF(A_CDRRMO!$B$5:$B$96,B7,A_CDRRMO!$S$5:$S$96) -> 10 | F7: =IF(SUMIF(A_CDRRMO!$B$5:$B$96,B7,A_CDRRMO!$R$5:$R$96)=0,"",SUMIF(A_CDRRMO!$B$5:$B$96,B7,A_CDRRMO!$Q$5:$Q$96)/SUMIF(A_CDRRMO!$B$5:$B$96,B7,A_CDRRMO!$R$5:$R$96)*4) -> 1.7727273 | G7: =IF(F7="","",IF(F7<0.5,"Absent",IF(F7<1.5,"Initial",IF(F7<2.5,"Developing",IF(F7<3.5,"Compliant","Advanced"))))) -> Developing | H7: =IF(SUMIF(A_CDRRMO!$B$5:$B$96,B7,A_CDRRMO!$T$5:$T$96)=0,"",SUMIF(A_CDRRMO!$B$5:$B$96,B7,A_CDRRMO!$U$5:$U$96)/SUMIF(A_CDRRMO!$B$5:$B$96,B7,A_CDRRMO!$T$5:$T$96)) -> 0.14285714 | I7: =COUNTIFS(A_CDRRMO!$B$5:$B$96,B7,A_CDRRMO!$N$5:$N$96,"High") -> 5 | J7: =IF(F7="",0,F7/4) -> 0.44318182
B8: A3 | C8: DRRM & Contingency Planning | D8: =COUNTIF(A_CDRRMO!$B$5:$B$96,B8) -> 7 | E8: =SUMIF(A_CDRRMO!$B$5:$B$96,B8,A_CDRRMO!$S$5:$S$96) -> 7 | F8: =IF(SUMIF(A_CDRRMO!$B$5:$B$96,B8,A_CDRRMO!$R$5:$R$96)=0,"",SUMIF(A_CDRRMO!$B$5:$B$96,B8,A_CDRRMO!$Q$5:$Q$96)/SUMIF(A_CDRRMO!$B$5:$B$96,B8,A_CDRRMO!$R$5:$R$96)*4) -> 3.1666667 | G8: =IF(F8="","",IF(F8<0.5,"Absent",IF(F8<1.5,"Initial",IF(F8<2.5,"Developing",IF(F8<3.5,"Compliant","Advanced"))))) -> Compliant | H8: =IF(SUMIF(A_CDRRMO!$B$5:$B$96,B8,A_CDRRMO!$T$5:$T$96)=0,"",SUMIF(A_CDRRMO!$B$5:$B$96,B8,A_CDRRMO!$U$5:$U$96)/SUMIF(A_CDRRMO!$B$5:$B$96,B8,A_CDRRMO!$T$5:$T$96)) -> 0.66666667 | I8: =COUNTIFS(A_CDRRMO!$B$5:$B$96,B8,A_CDRRMO!$N$5:$N$96,"High") -> 1 | J8: =IF(F8="",0,F8/4) -> 0.79166667
B9: A4 | C9: DRRM Financing & Fund Management | D9: =COUNTIF(A_CDRRMO!$B$5:$B$96,B9) -> 9 | E9: =SUMIF(A_CDRRMO!$B$5:$B$96,B9,A_CDRRMO!$S$5:$S$96) -> 8 | F9: =IF(SUMIF(A_CDRRMO!$B$5:$B$96,B9,A_CDRRMO!$R$5:$R$96)=0,"",SUMIF(A_CDRRMO!$B$5:$B$96,B9,A_CDRRMO!$Q$5:$Q$96)/SUMIF(A_CDRRMO!$B$5:$B$96,B9,A_CDRRMO!$R$5:$R$96)*4) -> 3.1176471 | G9: =IF(F9="","",IF(F9<0.5,"Absent",IF(F9<1.5,"Initial",IF(F9<2.5,"Developing",IF(F9<3.5,"Compliant","Advanced"))))) -> Compliant | H9: =IF(SUMIF(A_CDRRMO!$B$5:$B$96,B9,A_CDRRMO!$T$5:$T$96)=0,"",SUMIF(A_CDRRMO!$B$5:$B$96,B9,A_CDRRMO!$U$5:$U$96)/SUMIF(A_CDRRMO!$B$5:$B$96,B9,A_CDRRMO!$T$5:$T$96)) -> 0.83333333 | I9: =COUNTIFS(A_CDRRMO!$B$5:$B$96,B9,A_CDRRMO!$N$5:$N$96,"High") -> 1 | J9: =IF(F9="",0,F9/4) -> 0.77941176
B10: A5 | C10: Risk Assessment, Data & Knowledge Management | D10: =COUNTIF(A_CDRRMO!$B$5:$B$96,B10) -> 9 | E10: =SUMIF(A_CDRRMO!$B$5:$B$96,B10,A_CDRRMO!$S$5:$S$96) -> 9 | F10: =IF(SUMIF(A_CDRRMO!$B$5:$B$96,B10,A_CDRRMO!$R$5:$R$96)=0,"",SUMIF(A_CDRRMO!$B$5:$B$96,B10,A_CDRRMO!$Q$5:$Q$96)/SUMIF(A_CDRRMO!$B$5:$B$96,B10,A_CDRRMO!$R$5:$R$96)*4) -> 2.0555556 | G10: =IF(F10="","",IF(F10<0.5,"Absent",IF(F10<1.5,"Initial",IF(F10<2.5,"Developing",IF(F10<3.5,"Compliant","Advanced"))))) -> Developing | H10: =IF(SUMIF(A_CDRRMO!$B$5:$B$96,B10,A_CDRRMO!$T$5:$T$96)=0,"",SUMIF(A_CDRRMO!$B$5:$B$96,B10,A_CDRRMO!$U$5:$U$96)/SUMIF(A_CDRRMO!$B$5:$B$96,B10,A_CDRRMO!$T$5:$T$96)) -> 0.75 | I10: =COUNTIFS(A_CDRRMO!$B$5:$B$96,B10,A_CDRRMO!$N$5:$N$96,"High") -> 0 | J10: =IF(F10="",0,F10/4) -> 0.51388889
B11: A6 | C11: Early Warning & Risk Communication | D11: =COUNTIF(A_CDRRMO!$B$5:$B$96,B11) -> 7 | E11: =SUMIF(A_CDRRMO!$B$5:$B$96,B11,A_CDRRMO!$S$5:$S$96) -> 7 | F11: =IF(SUMIF(A_CDRRMO!$B$5:$B$96,B11,A_CDRRMO!$R$5:$R$96)=0,"",SUMIF(A_CDRRMO!$B$5:$B$96,B11,A_CDRRMO!$Q$5:$Q$96)/SUMIF(A_CDRRMO!$B$5:$B$96,B11,A_CDRRMO!$R$5:$R$96)*4) -> 2.2666667 | G11: =IF(F11="","",IF(F11<0.5,"Absent",IF(F11<1.5,"Initial",IF(F11<2.5,"Developing",IF(F11<3.5,"Compliant","Advanced"))))) -> Developing | H11: =IF(SUMIF(A_CDRRMO!$B$5:$B$96,B11,A_CDRRMO!$T$5:$T$96)=0,"",SUMIF(A_CDRRMO!$B$5:$B$96,B11,A_CDRRMO!$U$5:$U$96)/SUMIF(A_CDRRMO!$B$5:$B$96,B11,A_CDRRMO!$T$5:$T$96)) -> 0.25 | I11: =COUNTIFS(A_CDRRMO!$B$5:$B$96,B11,A_CDRRMO!$N$5:$N$96,"High") -> 3 | J11: =IF(F11="",0,F11/4) -> 0.56666667
B12: A7 | C12: Preparedness & Community Capacity | D12: =COUNTIF(A_CDRRMO!$B$5:$B$96,B12) -> 9 | E12: =SUMIF(A_CDRRMO!$B$5:$B$96,B12,A_CDRRMO!$S$5:$S$96) -> 8 | F12: =IF(SUMIF(A_CDRRMO!$B$5:$B$96,B12,A_CDRRMO!$R$5:$R$96)=0,"",SUMIF(A_CDRRMO!$B$5:$B$96,B12,A_CDRRMO!$Q$5:$Q$96)/SUMIF(A_CDRRMO!$B$5:$B$96,B12,A_CDRRMO!$R$5:$R$96)*4) -> 2.9333333 | G12: =IF(F12="","",IF(F12<0.5,"Absent",IF(F12<1.5,"Initial",IF(F12<2.5,"Developing",IF(F12<3.5,"Compliant","Advanced"))))) -> Compliant | H12: =IF(SUMIF(A_CDRRMO!$B$5:$B$96,B12,A_CDRRMO!$T$5:$T$96)=0,"",SUMIF(A_CDRRMO!$B$5:$B$96,B12,A_CDRRMO!$U$5:$U$96)/SUMIF(A_CDRRMO!$B$5:$B$96,B12,A_CDRRMO!$T$5:$T$96)) -> 0.8 | I12: =COUNTIFS(A_CDRRMO!$B$5:$B$96,B12,A_CDRRMO!$N$5:$N$96,"High") -> 1 | J12: =IF(F12="",0,F12/4) -> 0.73333333
B13: A8 | C13: Response Capability | D13: =COUNTIF(A_CDRRMO!$B$5:$B$96,B13) -> 9 | E13: =SUMIF(A_CDRRMO!$B$5:$B$96,B13,A_CDRRMO!$S$5:$S$96) -> 9 | F13: =IF(SUMIF(A_CDRRMO!$B$5:$B$96,B13,A_CDRRMO!$R$5:$R$96)=0,"",SUMIF(A_CDRRMO!$B$5:$B$96,B13,A_CDRRMO!$Q$5:$Q$96)/SUMIF(A_CDRRMO!$B$5:$B$96,B13,A_CDRRMO!$R$5:$R$96)*4) -> 1.6818182 | G13: =IF(F13="","",IF(F13<0.5,"Absent",IF(F13<1.5,"Initial",IF(F13<2.5,"Developing",IF(F13<3.5,"Compliant","Advanced"))))) -> Developing | H13: =IF(SUMIF(A_CDRRMO!$B$5:$B$96,B13,A_CDRRMO!$T$5:$T$96)=0,"",SUMIF(A_CDRRMO!$B$5:$B$96,B13,A_CDRRMO!$U$5:$U$96)/SUMIF(A_CDRRMO!$B$5:$B$96,B13,A_CDRRMO!$T$5:$T$96)) -> 0.375 | I13: =COUNTIFS(A_CDRRMO!$B$5:$B$96,B13,A_CDRRMO!$N$5:$N$96,"High") -> 5 | J13: =IF(F13="",0,F13/4) -> 0.42045455
B14: A9 | C14: Rehabilitation & Recovery | D14: =COUNTIF(A_CDRRMO!$B$5:$B$96,B14) -> 5 | E14: =SUMIF(A_CDRRMO!$B$5:$B$96,B14,A_CDRRMO!$S$5:$S$96) -> 5 | F14: =IF(SUMIF(A_CDRRMO!$B$5:$B$96,B14,A_CDRRMO!$R$5:$R$96)=0,"",SUMIF(A_CDRRMO!$B$5:$B$96,B14,A_CDRRMO!$Q$5:$Q$96)/SUMIF(A_CDRRMO!$B$5:$B$96,B14,A_CDRRMO!$R$5:$R$96)*4) -> 1.875 | G14: =IF(F14="","",IF(F14<0.5,"Absent",IF(F14<1.5,"Initial",IF(F14<2.5,"Developing",IF(F14<3.5,"Compliant","Advanced"))))) -> Developing | H14: =IF(SUMIF(A_CDRRMO!$B$5:$B$96,B14,A_CDRRMO!$T$5:$T$96)=0,"",SUMIF(A_CDRRMO!$B$5:$B$96,B14,A_CDRRMO!$U$5:$U$96)/SUMIF(A_CDRRMO!$B$5:$B$96,B14,A_CDRRMO!$T$5:$T$96)) -> 1 | I14: =COUNTIFS(A_CDRRMO!$B$5:$B$96,B14,A_CDRRMO!$N$5:$N$96,"High") -> 0 | J14: =IF(F14="",0,F14/4) -> 0.46875
B15: A10 | C15: Partnerships, M&E & Accountability | D15: =COUNTIF(A_CDRRMO!$B$5:$B$96,B15) -> 9 | E15: =SUMIF(A_CDRRMO!$B$5:$B$96,B15,A_CDRRMO!$S$5:$S$96) -> 9 | F15: =IF(SUMIF(A_CDRRMO!$B$5:$B$96,B15,A_CDRRMO!$R$5:$R$96)=0,"",SUMIF(A_CDRRMO!$B$5:$B$96,B15,A_CDRRMO!$Q$5:$Q$96)/SUMIF(A_CDRRMO!$B$5:$B$96,B15,A_CDRRMO!$R$5:$R$96)*4) -> 2.5 | G15: =IF(F15="","",IF(F15<0.5,"Absent",IF(F15<1.5,"Initial",IF(F15<2.5,"Developing",IF(F15<3.5,"Compliant","Advanced"))))) -> Compliant | H15: =IF(SUMIF(A_CDRRMO!$B$5:$B$96,B15,A_CDRRMO!$T$5:$T$96)=0,"",SUMIF(A_CDRRMO!$B$5:$B$96,B15,A_CDRRMO!$U$5:$U$96)/SUMIF(A_CDRRMO!$B$5:$B$96,B15,A_CDRRMO!$T$5:$T$96)) -> 0.5 | I15: =COUNTIFS(A_CDRRMO!$B$5:$B$96,B15,A_CDRRMO!$N$5:$N$96,"High") -> 1 | J15: =IF(F15="",0,F15/4) -> 0.625
B16: B1 | C16: EOC Legal Basis & Concept of Operations | D16: =COUNTIF(B_EOC!$B$5:$B$54,B16) -> 5 | E16: =SUMIF(B_EOC!$B$5:$B$54,B16,B_EOC!$S$5:$S$54) -> 5 | F16: =IF(SUMIF(B_EOC!$B$5:$B$54,B16,B_EOC!$R$5:$R$54)=0,"",SUMIF(B_EOC!$B$5:$B$54,B16,B_EOC!$Q$5:$Q$54)/SUMIF(B_EOC!$B$5:$B$54,B16,B_EOC!$R$5:$R$54)*4) -> 1.8461538 | G16: =IF(F16="","",IF(F16<0.5,"Absent",IF(F16<1.5,"Initial",IF(F16<2.5,"Developing",IF(F16<3.5,"Compliant","Advanced"))))) -> Developing | H16: =IF(SUMIF(B_EOC!$B$5:$B$54,B16,B_EOC!$T$5:$T$54)=0,"",SUMIF(B_EOC!$B$5:$B$54,B16,B_EOC!$U$5:$U$54)/SUMIF(B_EOC!$B$5:$B$54,B16,B_EOC!$T$5:$T$54)) -> 0 | I16: =COUNTIFS(B_EOC!$B$5:$B$54,B16,B_EOC!$N$5:$N$54,"High") -> 4 | J16: =IF(F16="",0,F16/4) -> 0.46153846
B17: B2 | C17: EOC Facility, Site & Resilience | D17: =COUNTIF(B_EOC!$B$5:$B$54,B17) -> 7 | E17: =SUMIF(B_EOC!$B$5:$B$54,B17,B_EOC!$S$5:$S$54) -> 0 | F17: =IF(SUMIF(B_EOC!$B$5:$B$54,B17,B_EOC!$R$5:$R$54)=0,"",SUMIF(B_EOC!$B$5:$B$54,B17,B_EOC!$Q$5:$Q$54)/SUMIF(B_EOC!$B$5:$B$54,B17,B_EOC!$R$5:$R$54)*4) | G17: =IF(F17="","",IF(F17<0.5,"Absent",IF(F17<1.5,"Initial",IF(F17<2.5,"Developing",IF(F17<3.5,"Compliant","Advanced"))))) | H17: =IF(SUMIF(B_EOC!$B$5:$B$54,B17,B_EOC!$T$5:$T$54)=0,"",SUMIF(B_EOC!$B$5:$B$54,B17,B_EOC!$U$5:$U$54)/SUMIF(B_EOC!$B$5:$B$54,B17,B_EOC!$T$5:$T$54)) | I17: =COUNTIFS(B_EOC!$B$5:$B$54,B17,B_EOC!$N$5:$N$54,"High") -> 0 | J17: =IF(F17="",0,F17/4) -> 0
B18: B3 | C18: EOC Communications & ICT | D18: =COUNTIF(B_EOC!$B$5:$B$54,B18) -> 6 | E18: =SUMIF(B_EOC!$B$5:$B$54,B18,B_EOC!$S$5:$S$54) -> 2 | F18: =IF(SUMIF(B_EOC!$B$5:$B$54,B18,B_EOC!$R$5:$R$54)=0,"",SUMIF(B_EOC!$B$5:$B$54,B18,B_EOC!$Q$5:$Q$54)/SUMIF(B_EOC!$B$5:$B$54,B18,B_EOC!$R$5:$R$54)*4) -> 2 | G18: =IF(F18="","",IF(F18<0.5,"Absent",IF(F18<1.5,"Initial",IF(F18<2.5,"Developing",IF(F18<3.5,"Compliant","Advanced"))))) -> Developing | H18: =IF(SUMIF(B_EOC!$B$5:$B$54,B18,B_EOC!$T$5:$T$54)=0,"",SUMIF(B_EOC!$B$5:$B$54,B18,B_EOC!$U$5:$U$54)/SUMIF(B_EOC!$B$5:$B$54,B18,B_EOC!$T$5:$T$54)) -> 0 | I18: =COUNTIFS(B_EOC!$B$5:$B$54,B18,B_EOC!$N$5:$N$54,"High") -> 1 | J18: =IF(F18="",0,F18/4) -> 0.5
B19: B4 | C19: EOC Organization & Staffing | D19: =COUNTIF(B_EOC!$B$5:$B$54,B19) -> 6 | E19: =SUMIF(B_EOC!$B$5:$B$54,B19,B_EOC!$S$5:$S$54) -> 5 | F19: =IF(SUMIF(B_EOC!$B$5:$B$54,B19,B_EOC!$R$5:$R$54)=0,"",SUMIF(B_EOC!$B$5:$B$54,B19,B_EOC!$Q$5:$Q$54)/SUMIF(B_EOC!$B$5:$B$54,B19,B_EOC!$R$5:$R$54)*4) -> 1.4 | G19: =IF(F19="","",IF(F19<0.5,"Absent",IF(F19<1.5,"Initial",IF(F19<2.5,"Developing",IF(F19<3.5,"Compliant","Advanced"))))) -> Initial | H19: =IF(SUMIF(B_EOC!$B$5:$B$54,B19,B_EOC!$T$5:$T$54)=0,"",SUMIF(B_EOC!$B$5:$B$54,B19,B_EOC!$U$5:$U$54)/SUMIF(B_EOC!$B$5:$B$54,B19,B_EOC!$T$5:$T$54)) -> 0 | I19: =COUNTIFS(B_EOC!$B$5:$B$54,B19,B_EOC!$N$5:$N$54,"High") -> 1 | J19: =IF(F19="",0,F19/4) -> 0.35
B20: B5 | C20: Information Management & Reporting | D20: =COUNTIF(B_EOC!$B$5:$B$54,B20) -> 7 | E20: =SUMIF(B_EOC!$B$5:$B$54,B20,B_EOC!$S$5:$S$54) -> 5 | F20: =IF(SUMIF(B_EOC!$B$5:$B$54,B20,B_EOC!$R$5:$R$54)=0,"",SUMIF(B_EOC!$B$5:$B$54,B20,B_EOC!$Q$5:$Q$54)/SUMIF(B_EOC!$B$5:$B$54,B20,B_EOC!$R$5:$R$54)*4) -> 1.4545455 | G20: =IF(F20="","",IF(F20<0.5,"Absent",IF(F20<1.5,"Initial",IF(F20<2.5,"Developing",IF(F20<3.5,"Compliant","Advanced"))))) -> Initial | H20: =IF(SUMIF(B_EOC!$B$5:$B$54,B20,B_EOC!$T$5:$T$54)=0,"",SUMIF(B_EOC!$B$5:$B$54,B20,B_EOC!$U$5:$U$54)/SUMIF(B_EOC!$B$5:$B$54,B20,B_EOC!$T$5:$T$54)) -> 0 | I20: =COUNTIFS(B_EOC!$B$5:$B$54,B20,B_EOC!$N$5:$N$54,"High") -> 2 | J20: =IF(F20="",0,F20/4) -> 0.36363636
B21: B6 | C21: Coordination & Resource Management | D21: =COUNTIF(B_EOC!$B$5:$B$54,B21) -> 6 | E21: =SUMIF(B_EOC!$B$5:$B$54,B21,B_EOC!$S$5:$S$54) -> 5 | F21: =IF(SUMIF(B_EOC!$B$5:$B$54,B21,B_EOC!$R$5:$R$54)=0,"",SUMIF(B_EOC!$B$5:$B$54,B21,B_EOC!$Q$5:$Q$54)/SUMIF(B_EOC!$B$5:$B$54,B21,B_EOC!$R$5:$R$54)*4) -> 1.2727273 | G21: =IF(F21="","",IF(F21<0.5,"Absent",IF(F21<1.5,"Initial",IF(F21<2.5,"Developing",IF(F21<3.5,"Compliant","Advanced"))))) -> Initial | H21: =IF(SUMIF(B_EOC!$B$5:$B$54,B21,B_EOC!$T$5:$T$54)=0,"",SUMIF(B_EOC!$B$5:$B$54,B21,B_EOC!$U$5:$U$54)/SUMIF(B_EOC!$B$5:$B$54,B21,B_EOC!$T$5:$T$54)) -> 0 | I21: =COUNTIFS(B_EOC!$B$5:$B$54,B21,B_EOC!$N$5:$N$54,"High") -> 2 | J21: =IF(F21="",0,F21/4) -> 0.31818182
B22: B7 | C22: EOC SOPs, Training, Exercises & Continuity | D22: =COUNTIF(B_EOC!$B$5:$B$54,B22) -> 6 | E22: =SUMIF(B_EOC!$B$5:$B$54,B22,B_EOC!$S$5:$S$54) -> 6 | F22: =IF(SUMIF(B_EOC!$B$5:$B$54,B22,B_EOC!$R$5:$R$54)=0,"",SUMIF(B_EOC!$B$5:$B$54,B22,B_EOC!$Q$5:$Q$54)/SUMIF(B_EOC!$B$5:$B$54,B22,B_EOC!$R$5:$R$54)*4) -> 2.0833333 | G22: =IF(F22="","",IF(F22<0.5,"Absent",IF(F22<1.5,"Initial",IF(F22<2.5,"Developing",IF(F22<3.5,"Compliant","Advanced"))))) -> Developing | H22: =IF(SUMIF(B_EOC!$B$5:$B$54,B22,B_EOC!$T$5:$T$54)=0,"",SUMIF(B_EOC!$B$5:$B$54,B22,B_EOC!$U$5:$U$54)/SUMIF(B_EOC!$B$5:$B$54,B22,B_EOC!$T$5:$T$54)) -> 0.25 | I22: =COUNTIFS(B_EOC!$B$5:$B$54,B22,B_EOC!$N$5:$N$54,"High") -> 1 | J22: =IF(F22="",0,F22/4) -> 0.52083333
C24: PART A - CDRRMO OVERALL | D24: =COUNTA(A_CDRRMO!$B$5:$B$96) -> 82 | E24: =SUM(A_CDRRMO!$S$5:$S$96) -> 80 | F24: =IF((SUM(A_CDRRMO!$R$5:$R$96))=0,"",(SUM(A_CDRRMO!$Q$5:$Q$96))/(SUM(A_CDRRMO!$R$5:$R$96))*4) -> 2.3795181 | G24: =IF(F24="","",IF(F24<0.5,"Absent",IF(F24<1.5,"Initial",IF(F24<2.5,"Developing",IF(F24<3.5,"Compliant","Advanced"))))) -> Developing | H24: =IF((SUM(A_CDRRMO!$T$5:$T$96))=0,"",(SUM(A_CDRRMO!$U$5:$U$96))/(SUM(A_CDRRMO!$T$5:$T$96))) -> 0.52941176 | I24: =COUNTIF(A_CDRRMO!$N$5:$N$96,"High") -> 19 | J24: =IF(F24="",0,F24/4) -> 0.59487952
C25: PART B - EOC OVERALL | D25: =COUNTA(B_EOC!$B$5:$B$54) -> 43 | E25: =SUM(B_EOC!$S$5:$S$54) -> 28 | F25: =IF((SUM(B_EOC!$R$5:$R$54))=0,"",(SUM(B_EOC!$Q$5:$Q$54))/(SUM(B_EOC!$R$5:$R$54))*4) -> 1.6612903 | G25: =IF(F25="","",IF(F25<0.5,"Absent",IF(F25<1.5,"Initial",IF(F25<2.5,"Developing",IF(F25<3.5,"Compliant","Advanced"))))) -> Developing | H25: =IF((SUM(B_EOC!$T$5:$T$54))=0,"",(SUM(B_EOC!$U$5:$U$54))/(SUM(B_EOC!$T$5:$T$54))) -> 0.05 | I25: =COUNTIF(B_EOC!$N$5:$N$54,"High") -> 11 | J25: =IF(F25="",0,F25/4) -> 0.41532258
C26: INSTITUTIONAL MATURITY INDEX (A+B) | D26: =COUNTA(A_CDRRMO!$B$5:$B$96)+COUNTA(B_EOC!$B$5:$B$54) -> 125 | E26: =SUM(A_CDRRMO!$S$5:$S$96)+SUM(B_EOC!$S$5:$S$54) -> 108 | F26: =IF((SUM(A_CDRRMO!$R$5:$R$96)+SUM(B_EOC!$R$5:$R$54))=0,"",(SUM(A_CDRRMO!$Q$5:$Q$96)+SUM(B_EOC!$Q$5:$Q$54))/(SUM(A_CDRRMO!$R$5:$R$96)+SUM(B_EOC!$R$5:$R$54))*4) -> 2.1842105 | G26: =IF(F26="","",IF(F26<0.5,"Absent",IF(F26<1.5,"Initial",IF(F26<2.5,"Developing",IF(F26<3.5,"Compliant","Advanced"))))) -> Developing | H26: =IF((SUM(A_CDRRMO!$T$5:$T$96)+SUM(B_EOC!$T$5:$T$54))=0,"",(SUM(A_CDRRMO!$U$5:$U$96)+SUM(B_EOC!$U$5:$U$54))/(SUM(A_CDRRMO!$T$5:$T$96)+SUM(B_EOC!$T$5:$T$54))) -> 0.3943662 | I26: =COUNTIF(A_CDRRMO!$N$5:$N$96,"High")+COUNTIF(B_EOC!$N$5:$N$54,"High") -> 30 | J26: =IF(F26="",0,F26/4) -> 0.54605263
C27: PART C - INTERFACE INDEX (separate; not in IMI) | D27: =COUNTA(C_Interface!$B$5:$B$24) -> 15 | E27: =SUM(C_Interface!$S$5:$S$24) -> 7 | F27: =IF(SUM(C_Interface!$R$5:$R$24)=0,"",SUM(C_Interface!$Q$5:$Q$24)/SUM(C_Interface!$R$5:$R$24)*4) -> 1.2857143 | G27: =IF(F27="","",IF(F27<0.5,"Absent",IF(F27<1.5,"Initial",IF(F27<2.5,"Developing",IF(F27<3.5,"Compliant","Advanced"))))) -> Initial | H27: n/a | I27: =COUNTIF(C_Interface!$N$5:$N$24,"High") -> 1 | J27: =IF(F27="",0,F27/4) -> 0.32142857
B28: Notes: 'Indicators' counts all indicators in the domain; 'Scored' excludes NA and blank. Mandatory Compliance = share of scored Mandatory indicators rated 3-4. A domain is considered compliant only when Mandatory Compliance is 100%. Part C (interface) is scored with the same rubric but reported separately because the items are owned by other offices.

Sheet Profile
B2: ASSESSMENT PROFILE
B4: LGU | C4: City of Ormoc
B5: Province / Region | C5: Leyte / Region VIII (Eastern Visayas)
B6: Income class / LGU type | C6: 1st-class independent component city (ICC)
B7: Number of barangays | C7: 85 (PSA PSGC since 4Q 2022; City Ord. No. 052 s.2021, plebiscite 8 Oct 2022). The DRRM 10-Year Plan still shows 110.
B8: Office assessed | C8: City DRRM Office and City Emergency Operations Center
B9: CDRRMO Head | C9: Ciriaco Tolibao
B10: Assessment period (from - to) | C10: October 2026 (field scoring by the CDRRMO team; desk review completed 30 Oct 2026)
B11: Lead assessor | C11: Alvin M. Silva, Development of MOP on EOC and DRRM Consultant
B12: Assessment team members | C12: CDRRMO Planning, Operations and Admin section staff (names to be entered by the City)
B13: Key informants interviewed (names/positions) | C13: Positions only, per RA 10173: CDRRMO section staff (FGDs). CPDO KII pending (A5.5, A5.6). Names kept in the lead assessor's field notes, not in this workbook.
B14: FGD groups conducted | C14: 3 FGDs: CDRRMO Planning Section, Operations Section, Admin Section
B15: Sites inspected | C15: None yet. Pending: EOC/OpCen facility, warehouse, sampled evacuation centers (Part B OBS/TST)
... B18: Validated by (name/position) | C18: Pending
B20: Pre-filled values come from the consultancy scope; confirm or correct them with CDRRMO.

Sheet A_CDRRMO
A1: PART A - CDRRMO INSTITUTIONAL CAPACITY ASSESSMENT
A2: Score in yellow cells only. Type: M = Mandatory (legal/policy compliance), GP = Good practice. Methods: DR document review, KII interview, FGD focus group, OBS observation, TST test/demonstration.
A4: ID | B4: Domain | C4: Indicator | D4: Standard / Policy Reference | E4: Type (M/GP) | F4: Means of Verification | G4: Method | H4: Weight | I4: Score (0-4/NA) | J4: Evidence Observed | K4: Gap / Remarks | L4: Recommended Action | M4: Gap Priority Score | N4: Priority | O4: Compliance Status | P4: Feeds Manual Chapter | Q4: w*score | R4: w*4 | S4: Scored | T4: M scored | U4: M compliant
A5: A1 LEGAL MANDATE & DRRM GOVERNANCE - CDRRMC/CDRRMO legal basis, council functionality, policy instruments
A6: A1.1 | B6: A1 | C6: City ordinance/EO creating the CDRRMO as a regular office (not ad hoc), with defined functions mirroring RA 10121 Sec. 12(c) | D6: RA 10121 Sec. 12; IRR Rule 6; JMC 2014-1 | E6: M | F6: Ordinance/EO; Sangguniang Panlungsod records | G6: DR | H6: 3 | I6: 2 | J6: F: EO covers both the CDRRMO and BDRRMOs and follows minimum requirements; amended, but no ordinance on BDRRMOs. DR: 10-Yr Plan lists hiring of 4+4+2 CDRRMO plantilla positions, so the office is not yet staffed as a full department. | K6: No ordinance establishing the CDRRMO as a regular department with JMC 2014-1 divisions; the EO is the only basis. (Field FGD notes formerly typed here were moved to A2.4, A2.6, A2.10 and B6.1.) | L6: Draft an ordinance creating the CDRRMO as a regular department with Admin & Training, Research & Planning and Operations & Warning divisions and their functions (RA 10121 Sec. 12(c); JMC 2014-1). Attach the organogram and staffing pattern from MOO Ch.2. | M6: =IF(ISNUMBER(I6),(4-I6)*H6*IF(E6="M",1.5,1),"") -> 9 | N6: =IF(M6="","",IF(M6>=9,"High",IF(M6>=4,"Medium","Low"))) -> High | O6: =IF(NOT(ISNUMBER(I6)),IF(I6="NA","N/A","Not scored"),IF(E6="M",IF(I6>=3,"Compliant","Non-compliant"),IF(I6>=3,"Meets GP","Below GP"))) -> Non-compliant | P6: MOO Ch.1 Legal & Institutional Framework | Q6: =IF(ISNUMBER(I6),I6*H6,0) -> 6 | R6: =IF(ISNUMBER(I6),4*H6,0) -> 12 | S6: =IF(ISNUMBER(I6),1,0) -> 1 | T6: =IF(AND(E6="M",ISNUMBER(I6)),1,0) -> 1 | U6: =IF(AND(E6="M",ISNUMBER(I6)),IF(I6>=3,1,0),0) -> 0
A7: A1.2 | B7: A1 | C7: CDRRMC constituted with complete membership per RA 10121 Sec. 11 (incl. CSO and private sector reps) | D7: RA 10121 Sec. 11 | E7: M | F7: EO on CDRRMC composition; list of members | G7: DR | H7: 2 | I7: 2 | J7: F: CDRRMC EO needs updating to cover the mandated representations; minimum of 4 CSO seats not yet met. | K7: Composition incomplete against RA 10121 Sec. 11 (incl. CSO and private-sector seats). (Operations FGD notes formerly here were moved to B6.1 and B7.1.) | L7: Issue an updated EO on CDRRMC composition listing every RA 10121 Sec. 11 seat by office, with at least 4 accredited CSOs and a private-sector seat (e.g., EDC). Record the roster as an MOO Ch.1 annex and review it yearly. | M7: =IF(ISNUMBER(I7),(4-I7)*H7*IF(E7="M",1.5,1),"") -> 6 | N7: =IF(M7="","",IF(M7>=9,"High",IF(M7>=4,"Medium","Low"))) -> Medium | O7: =IF(NOT(ISNUMBER(I7)),IF(I7="NA","N/A","Not scored"),IF(E7="M",IF(I7>=3,"Compliant","Non-compliant"),IF(I7>=3,"Meets GP","Below GP"))) -> Non-compliant | P7: MOO Ch.1 | Q7: =IF(ISNUMBER(I7),I7*H7,0) -> 4 | R7: =IF(ISNUMBER(I7),4*H7,0) -> 8 | S7: =IF(ISNUMBER(I7),1,0) -> 1 | T7: =IF(AND(E7="M",ISNUMBER(I7)),1,0) -> 1 | U7: =IF(AND(E7="M",ISNUMBER(I7)),IF(I7>=3,1,0),0) -> 0
A8: A1.3 | B8: A1 | C8: CDRRMC meets at least quarterly (and as needed); minutes and resolutions on file | D8: RA 10121 Sec. 11; GKS/SGLG functionality criteria | E8: M | F8: Minutes, attendance, resolutions (last 4 quarters) | G8: DR, KII | H8: 2 | I8: 4 | J8: F: scored 4 (quarterly meetings, minutes and resolutions on file). DR: CDRRMC Res. No. 1 s.2023 approved the 10-Yr Plan. | K8: Validate with the last 4 quarters of minutes and attendance. (Admin FGD notes formerly here were moved to A2.4, A2.6 and A2.10.) | L8: Keep the quarterly schedule; add a standing agenda item on RA 12287 readiness and the action plan from this assessment. Use the minutes template in MOO Ch.1. | M8: =IF(ISNUMBER(I8),(4-I8)*H8*IF(E8="M",1.5,1),"") -> 0 | N8: =IF(M8="","",IF(M8>=9,"High",IF(M8>=4,"Medium","Low"))) -> Low | O8: =IF(NOT(ISNUMBER(I8)),IF(I8="NA","N/A","Not scored"),IF(E8="M",IF(I8>=3,"Compliant","Non-compliant"),IF(I8>=3,"Meets GP","Below GP"))) -> Compliant | P8: MOO Ch.1 | Q8: =IF(ISNUMBER(I8),I8*H8,0) -> 8 | R8: =IF(ISNUMBER(I8),4*H8,0) -> 8 | S8: =IF(ISNUMBER(I8),1,0) -> 1 | T8: =IF(AND(E8="M",ISNUMBER(I8)),1,0) -> 1 | U8: =IF(AND(E8="M",ISNUMBER(I8)),IF(I8>=3,1,0),0) -> 1
A9: A1.4 | B9: A1 | C9: CDRRMO serves as CDRRMC secretariat with documented secretariat procedures | D9: RA 10121 Sec. 12(c)(17) | E9: M | F9: Secretariat SOP; agenda/minutes templates | G9: DR, KII | H9: 1 | I9: 4 | J9: F: scored 4; CDRRMO serves as secretariat. | K9: Validate: secretariat SOP and agenda/minutes templates to be sighted in the workshop. | L9: Write the secretariat procedure (notice, agenda, quorum, minutes, resolutions, tracking) into MOO Ch.2. | M9: =IF(ISNUMBER(I9),(4-I9)*H9*IF(E9="M",1.5,1),"") -> 0 | N9: =IF(M9="","",IF(M9>=9,"High",IF(M9>=4,"Medium","Low"))) -> Low | O9: =IF(NOT(ISNUMBER(I9)),IF(I9="NA","N/A","Not scored"),IF(E9="M",IF(I9>=3,"Compliant","Non-compliant"),IF(I9>=3,"Meets GP","Below GP"))) -> Compliant | P9: MOO Ch.2 Office Organization | Q9: =IF(ISNUMBER(I9),I9*H9,0) -> 4 | R9: =IF(ISNUMBER(I9),4*H9,0) -> 4 | S9: =IF(ISNUMBER(I9),1,0) -> 1 | T9: =IF(AND(E9="M",ISNUMBER(I9)),1,0) -> 1 | U9: =IF(AND(E9="M",ISNUMBER(I9)),IF(I9>=3,1,0),0) -> 1
A10: A1.5 | B10: A1 | C10: Local DRRM-related ordinances in force (e.g., pre-emptive/forced evacuation, no-build zones, hazard-based zoning) | D10: RA 10121 Sec. 12(c)(19); RA 7160; CLUP/ZO | E10: GP | F10: Ordinances; ZO; enforcement records | G10: DR | H10: 2 | I10: 3 | J10: F: pre-emptive/forced evacuation ordinance in force but needs amendment; granular class suspension needed. DR: CLUP/ZO 2017-2027 in force with Water Code river easements, a 5-m easement on the Marina Fault trace and no-build zones, but no flood, landslide or storm-surge overlay zone (its overlays are heritage, critical habitat, eco-tourism, KBA, TOD and urban corridor). 10-Yr Plan cites an approved Shelter Plan. | K10: Evacuation ordinance lacks procedural steps (who orders, triggers, enforcement); class-suspension rules not barangay-specific; ZO has no hazard overlay zones. | L10: Amend the evacuation ordinance to add procedural statements: triggers tied to the warning-action matrix (A6.2), authority to order, assistance to PWD/elderly, livestock and pets (RA 12287 IRR Rule IV), and enforcement. Add granular (barangay/school-level) class and work suspension. In the CLUP/ZO update, add flood, landslide, storm-surge, liquefaction and tsunami overlay zones (CDRA MDA 1). | M10: =IF(ISNUMBER(I10),(4-I10)*H10*IF(E10="M",1.5,1),"") -> 2 | N10: =IF(M10="","",IF(M10>=9,"High",IF(M10>=4,"Medium","Low"))) -> Low | O10: =IF(NOT(ISNUMBER(I10)),IF(I10="NA","N/A","Not scored"),IF(E10="M",IF(I10>=3,"Compliant","Non-compliant"),IF(I10>=3,"Meets GP","Below GP"))) -> Meets GP | P10: MOO Ch.1 | Q10: =IF(ISNUMBER(I10),I10*H10,0) -> 6 | R10: =IF(ISNUMBER(I10),4*H10,0) -> 8 | S10: =IF(ISNUMBER(I10),1,0) -> 1 | T10: =IF(AND(E10="M",ISNUMBER(I10)),1,0) -> 0 | U10: =IF(AND(E10="M",ISNUMBER(I10)),IF(I10>=3,1,0),0) -> 0
A11: A1.6 | B11: A1 | C11: Protocol for declaring a State of Calamity, incl. CDRRMC recommendation steps and post-declaration measures (State of Imminent Disaster now assessed separately under A1.8) | D11: RA 10121 Sec. 16 | E11: M | F11: Protocol/SOP; past CDRRMC resolutions | G11: DR, KII | H11: 3 | I11: 3 | J11: F: scored 4, 'innate in the policy'; confusion noted on national declarations (e.g., San Juanico Bridge closure). DR: 10-Yr Plan records a State of Calamity declaration (Res. No. 354) for TS Urduja 2017. | K11: Assessor adjustment 4 -> 3: past use is shown, but no stand-alone written protocol and no test/AAR showing improvement were cited, which a 4 requires. v1.1 limits this item to State of Calamity; the State of Imminent Disaster is now A1.8. | L11: Write a State of Calamity protocol in MOO Ch.1: criteria (NDRRMC Memo on SoC criteria), RDANA/PDNA basis, CDRRMC recommendation, SP resolution template, post-declaration measures (price freeze, QRF use, reporting). Add a note on how to read national/regional declarations that affect Ormoc. | M11: =IF(ISNUMBER(I11),(4-I11)*H11*IF(E11="M",1.5,1),"") -> 4.5 | N11: =IF(M11="","",IF(M11>=9,"High",IF(M11>=4,"Medium","Low"))) -> Medium | O11: =IF(NOT(ISNUMBER(I11)),IF(I11="NA","N/A","Not scored"),IF(E11="M",IF(I11>=3,"Compliant","Non-compliant"),IF(I11>=3,"Meets GP","Below GP"))) -> Compliant | P11: MOO Ch.1 | Q11: =IF(ISNUMBER(I11),I11*H11,0) -> 9 | R11: =IF(ISNUMBER(I11),4*H11,0) -> 12 | S11: =IF(ISNUMBER(I11),1,0) -> 1 | T11: =IF(AND(E11="M",ISNUMBER(I11)),1,0) -> 1 | U11: =IF(AND(E11="M",ISNUMBER(I11)),IF(I11>=3,1,0),0) -> 1
A12: A1.7 | B12: A1 | C12: DRRM is represented in City Development Council and Local Finance Committee deliberations | D12: RA 7160; JMC 2013-1 | E12: GP | F12: Minutes; LDC/LFC membership | G12: DR, KII | H12: 1 | I12: 4 | J12: F: scored 4; DRRM represented in CDC and LFC. | K12: Validate with CDC/LFC minutes. | L12: Keep representation; use the LFC seat to secure the AA line (A4.6) and the EOC budget (B7.5) in the FY2028 budget call. | M12: =IF(ISNUMBER(I12),(4-I12)*H12*IF(E12="M",1.5,1),"") -> 0 | N12: =IF(M12="","",IF(M12>=9,"High",IF(M12>=4,"Medium","Low"))) -> Low | O12: =IF(NOT(ISNUMBER(I12)),IF(I12="NA","N/A","Not scored"),IF(E12="M",IF(I12>=3,"Compliant","Non-compliant"),IF(I12>=3,"Meets GP","Below GP"))) -> Meets GP | P12: MOO Ch.1 | Q12: =IF(ISNUMBER(I12),I12*H12,0) -> 4 | R12: =IF(ISNUMBER(I12),4*H12,0) -> 4 | S12: =IF(ISNUMBER(I12),1,0) -> 1 | T12: =IF(AND(E12="M",ISNUMBER(I12)),1,0) -> 0 | U12: =IF(AND(E12="M",ISNUMBER(I12)),IF(I12>=3,1,0),0) -> 0
A13: A1.8 | B13: A1 | C13: State of Imminent Disaster procedure: CDRRMC coordinates with RDRRMC VIII when the pre-disaster risk assessment shows reasonable certainty of severe impact; request format to RDRRMC (24-hour reply); Mayor's EO template; adoption rule when the Region (or Province, applicability to an ICC to be confirmed) is declared; lifting grounds and authority | D13: RA 12287; RA 12287 IRR (2026) Rule II Sec. 6; Rule III Secs. 2-4 | E13: M | F13: SOP; EO template; CDRRMC resolution and RDRRMC request templates | G13: DR, KII | H13: 3 | I13: 1 | J13: DR: RA 12287 IRR signed 14 Sep 2026; F (A4.6): AA arrangements 'not in place yet at local level, IRR for cascading'. No local SID SOP, EO template or RDRRMC request template found. | K13: Mandatory new requirement not yet in place: request to RDRRMC VIII (24-h reply), Mayor's EO, adoption rule, lifting grounds. | L13: Draft the State of Imminent Disaster procedure (IRR Rule II Sec. 6; Rule III Secs. 2-4): PDRA trigger, CDRRMC resolution, request to RDRRMC VIII, Mayor's EO template, adoption rule, lifting and the 45-day report (A10.8). Confirm with OCD VIII whether a Provincial declaration applies to an ICC. Walk it through in a tabletop to reach score 3. | M13: =IF(ISNUMBER(I13),(4-I13)*H13*IF(E13="M",1.5,1),"") -> 13.5 | N13: =IF(M13="","",IF(M13>=9,"High",IF(M13>=4,"Medium","Low"))) -> High | O13: =IF(NOT(ISNUMBER(I13)),IF(I13="NA","N/A","Not scored"),IF(E13="M",IF(I13>=3,"Compliant","Non-compliant"),IF(I13>=3,"Meets GP","Below GP"))) -> Non-compliant | P13: MOO Ch.1 / EOC Ch.2 | Q13: =IF(ISNUMBER(I13),I13*H13,0) -> 3 | R13: =IF(ISNUMBER(I13),4*H13,0) -> 12 | S13: =IF(ISNUMBER(I13),1,0) -> 1 | T13: =IF(AND(E13="M",ISNUMBER(I13)),1,0) -> 1 | U13: =IF(AND(E13="M",ISNUMBER(I13)),IF(I13>=3,1,0),0) -> 0
A14: A2 ORGANIZATION, STAFFING & HUMAN RESOURCES - JMC 2014-1 structure, plantilla, 24/7 capacity, competencies
A15: A2.1 | B15: A2 | C15: Organizational structure follows JMC 2014-1: Head + Administration & Training, Research & Planning, and Operations & Warning divisions | D15: NDRRMC-DILG-DBM-CSC JMC 2014-1 | E15: M | F15: Approved organogram; plantilla | G15: DR | H15: 3 | I15: 2 | J15: F: scored 2. DR: 10-Yr Plan SWOC says required CDRRMO positions exist but are not filled; FGDs show Planning, Operations and Admin sections exist. | K15: Divisions exist as sections, but not as an approved JMC 2014-1 structure; normal-operations tasks and response tasks are mixed (Planning FGD). | L15: Adopt the JMC 2014-1 organogram (Head + 3 divisions) with separate normal-operations and response (EOC) roles, through the ordinance in A1.1 and MOO Ch.2. | M15: =IF(ISNUMBER(I15),(4-I15)*H15*IF(E15="M",1.5,1),"") -> 9 | N15: =IF(M15="","",IF(M15>=9,"High",IF(M15>=4,"Medium","Low"))) -> High | O15: =IF(NOT(ISNUMBER(I15)),IF(I15="NA","N/A","Not scored"),IF(E15="M",IF(I15>=3,"Compliant","Non-compliant"),IF(I15>=3,"Meets GP","Below GP"))) -> Non-compliant | P15: MOO Ch.2 Office Organization | Q15: =IF(ISNUMBER(I15),I15*H15,0) -> 6 | R15: =IF(ISNUMBER(I15),4*H15,0) -> 12 | S15: =IF(ISNUMBER(I15),1,0) -> 1 | T15: =IF(AND(E15="M",ISNUMBER(I15)),1,0) -> 1 | U15: =IF(AND(E15="M",ISNUMBER(I15)),IF(I15>=3,1,0),0) -> 0
A16: A2.2 | B16: A2 | C16: CDRRMO Head is a permanent plantilla position filled by a qualified appointee | D16: RA 10121 Sec. 12(b); JMC 2014-1 | E16: M | F16: Appointment; PDS vs CSC QS | G16: DR | H16: 3 | I16: 4 | J16: F: scored 4; permanent Head appointed. DR: 10-Yr Plan names the CDRRMO Head (Ciriaco Tolibao). | K16: Validate appointment papers vs CSC QS. | L16: Maintain; document succession (OIC order of precedence) in MOO Ch.2. | M16: =IF(ISNUMBER(I16),(4-I16)*H16*IF(E16="M",1.5,1),"") -> 0 | N16: =IF(M16="","",IF(M16>=9,"High",IF(M16>=4,"Medium","Low"))) -> Low | O16: =IF(NOT(ISNUMBER(I16)),IF(I16="NA","N/A","Not scored"),IF(E16="M",IF(I16>=3,"Compliant","Non-compliant"),IF(I16>=3,"Meets GP","Below GP"))) -> Compliant | P16: MOO Ch.2 | Q16: =IF(ISNUMBER(I16),I16*H16,0) -> 12 | R16: =IF(ISNUMBER(I16),4*H16,0) -> 12 | S16: =IF(ISNUMBER(I16),1,0) -> 1 | T16: =IF(AND(E16="M",ISNUMBER(I16)),1,0) -> 1 | U16: =IF(AND(E16="M",ISNUMBER(I16)),IF(I16>=3,1,0),0) -> 1
A17: A2.3 | B17: A2 | C17: Minimum plantilla positions per JMC 2014-1 created and filled (ratio of filled/required) | D17: JMC 2014-1; CSC QS | E17: M | F17: Plantilla of Personnel; vacancy list | G17: DR | H17: 3 | I17: 2 | J17: F: scored 4. DR: 10-Yr Plan SWOC says required positions are not filled and its PPAs include hiring 4+4+2 plantilla items plus a maintenance engineer and property custodian. | K17: Assessor adjustment 4 -> 2 under the conflicting-evidence rule (take the lower). Restore if the current Plantilla of Personnel shows all JMC 2014-1 minimum positions filled. | L17: Get the Plantilla of Personnel and vacancy list; compute filled/required. Request creation and funding of the 10 planned items in the FY2028 budget, prioritising Operations & Warning (24/7 OpCen) and Research & Planning (GIS). | M17: =IF(ISNUMBER(I17),(4-I17)*H17*IF(E17="M",1.5,1),"") -> 9 | N17: =IF(M17="","",IF(M17>=9,"High",IF(M17>=4,"Medium","Low"))) -> High | O17: =IF(NOT(ISNUMBER(I17)),IF(I17="NA","N/A","Not scored"),IF(E17="M",IF(I17>=3,"Compliant","Non-compliant"),IF(I17>=3,"Meets GP","Below GP"))) -> Non-compliant | P17: MOO Ch.2 | Q17: =IF(ISNUMBER(I17),I17*H17,0) -> 6 | R17: =IF(ISNUMBER(I17),4*H17,0) -> 12 | S17: =IF(ISNUMBER(I17),1,0) -> 1 | T17: =IF(AND(E17="M",ISNUMBER(I17)),1,0) -> 1 | U17: =IF(AND(E17="M",ISNUMBER(I17)),IF(I17>=3,1,0),0) -> 0
A18: A2.4 | B18: A2 | C18: Job descriptions/position descriptions defined for every position, aligned to RA 10121 functions | D18: CSC rules; JMC 2014-1 | E18: M | F18: JDs/PDFs; IPCR/OPCR | G18: DR | H18: 2 | I18: 2 | J18: F: scored 2. Admin FGD: 'clearer job description per staff'; no monitoring tool for individual performance. | K18: JDs not defined per position; Admin functions bypassed in some activities. | L18: Write position descriptions for every CDRRMO and EOC role (MOO annex), aligned to RA 10121 functions; link them to IPCR/OPCR targets. | M18: =IF(ISNUMBER(I18),(4-I18)*H18*IF(E18="M",1.5,1),"") -> 6 | N18: =IF(M18="","",IF(M18>=9,"High",IF(M18>=4,"Medium","Low"))) -> Medium | O18: =IF(NOT(ISNUMBER(I18)),IF(I18="NA","N/A","Not scored"),IF(E18="M",IF(I18>=3,"Compliant","Non-compliant"),IF(I18>=3,"Meets GP","Below GP"))) -> Non-compliant | P18: MOO Ch.2 / Annex JDs | Q18: =IF(ISNUMBER(I18),I18*H18,0) -> 4 | R18: =IF(ISNUMBER(I18),4*H18,0) -> 8 | S18: =IF(ISNUMBER(I18),1,0) -> 1 | T18: =IF(AND(E18="M",ISNUMBER(I18)),1,0) -> 1 | U18: =IF(AND(E18="M",ISNUMBER(I18)),IF(I18>=3,1,0),0) -> 0
A19: A2.5 | B19: A2 | C19: 24/7 operations capability with documented shift roster (Operations Center/Duty officers) | D19: RA 10121 Sec. 12(c)(16); EOC guidelines | E19: M | F19: Duty roster (last 3 months); logbook | G19: DR, OBS | H19: 3 | I19: 1 | J19: F: attached SOP covers EOC activation only, not an SP-approved OpCen SOP for normal operations. DR: 10-Yr Plan says the Operations Center runs 24/7 with trained personnel, but operations need a manual/SOP; 'Operations Center SOP/Manual' is a 2023-24 PPA. | K19: 24/7 operation exists in practice but no approved normal-operations (White) SOP and roster. | L19: Write the OpCen normal-operations SOP (shifts, handover, monitoring, logbook, reporting times 6AM/6PM per RDRRMC8 Res. 12-006) as EOC Manual Ch.4/Ch.5, using the RDRRMOC SOPG 2022 forms (turn-over document, swapping form, duty composition by alert level); have it approved and keep 3 months of rosters as proof of use. | M19: =IF(ISNUMBER(I19),(4-I19)*H19*IF(E19="M",1.5,1),"") -> 13.5 | N19: =IF(M19="","",IF(M19>=9,"High",IF(M19>=4,"Medium","Low"))) -> High | O19: =IF(NOT(ISNUMBER(I19)),IF(I19="NA","N/A","Not scored"),IF(E19="M",IF(I19>=3,"Compliant","Non-compliant"),IF(I19>=3,"Meets GP","Below GP"))) -> Non-compliant | P19: MOO Ch.4 Operations / EOC Ch.4 | Q19: =IF(ISNUMBER(I19),I19*H19,0) -> 3 | R19: =IF(ISNUMBER(I19),4*H19,0) -> 12 | S19: =IF(ISNUMBER(I19),1,0) -> 1 | T19: =IF(AND(E19="M",ISNUMBER(I19)),1,0) -> 1 | U19: =IF(AND(E19="M",ISNUMBER(I19)),IF(I19>=3,1,0),0) -> 0
A20: A2.6 | B20: A2 | C20: Training needs analysis done and competency-based training plan for staff (ICS, BLS/SFA, WASAR, CSSR, MOSAR, EOC, PDNA, GIS) | D20: RA 10121 Sec. 14; OCD/DRRM Training Institute curricula | E20: GP | F20: TNA; training plan; certificates | G20: DR, KII | H20: 2 | I20: 1 | J20: F: scored 1. Planning FGD: no training needs assessment plan; Admin FGD: TNA proposals not routed to Planning. DR: 10-Yr Plan lists ICS all levels, EOC Management, MDM, CCCM, RDANA and PDNA training. | K20: No TNA or competency-based training plan. | L20: Run a TNA for all CDRRMO/EOC staff against the competency list (ICS, BLS/SFA, WASAR, CSSR, EOC, PDNA, GIS); produce a 3-year training plan with OCD VIII courses in MOO Ch.6. | M20: =IF(ISNUMBER(I20),(4-I20)*H20*IF(E20="M",1.5,1),"") -> 6 | N20: =IF(M20="","",IF(M20>=9,"High",IF(M20>=4,"Medium","Low"))) -> Medium | O20: =IF(NOT(ISNUMBER(I20)),IF(I20="NA","N/A","Not scored"),IF(E20="M",IF(I20>=3,"Compliant","Non-compliant"),IF(I20>=3,"Meets GP","Below GP"))) -> Below GP | P20: MOO Ch.6 Capacity Development | Q20: =IF(ISNUMBER(I20),I20*H20,0) -> 2 | R20: =IF(ISNUMBER(I20),4*H20,0) -> 8 | S20: =IF(ISNUMBER(I20),1,0) -> 1 | T20: =IF(AND(E20="M",ISNUMBER(I20)),1,0) -> 0 | U20: =IF(AND(E20="M",ISNUMBER(I20)),IF(I20>=3,1,0),0) -> 0
A21: A2.7 | B21: A2 | C21: Personnel welfare and safety: insurance, hazard pay, PPE, psychosocial support for responders | D21: RA 10121 Sec. 12; RA 11036 (MHPSS); CSC rules | E21: M | F21: Insurance policy; PPE inventory; MHPSS program | G21: DR, KII | H21: 2 | I21: 1 | J21: F: scored 1. DR: 10-Yr Plan lists responder care and insurance for ACDVs as planned PPAs. | K21: No insurance, hazard pay, PPE or MHPSS programme documented for responders. | L21: Adopt a responder welfare policy: group accident insurance (staff and accredited volunteers), PPE issue list, rest cycles, MHPSS referral with CHO (RA 11036). Memo 131 also requires EOC personnel welfare. | M21: =IF(ISNUMBER(I21),(4-I21)*H21*IF(E21="M",1.5,1),"") -> 9 | N21: =IF(M21="","",IF(M21>=9,"High",IF(M21>=4,"Medium","Low"))) -> High | O21: =IF(NOT(ISNUMBER(I21)),IF(I21="NA","N/A","Not scored"),IF(E21="M",IF(I21>=3,"Compliant","Non-compliant"),IF(I21>=3,"Meets GP","Below GP"))) -> Non-compliant | P21: MOO Ch.2 / Ch.4 | Q21: =IF(ISNUMBER(I21),I21*H21,0) -> 2 | R21: =IF(ISNUMBER(I21),4*H21,0) -> 8 | S21: =IF(ISNUMBER(I21),1,0) -> 1 | T21: =IF(AND(E21="M",ISNUMBER(I21)),1,0) -> 1 | U21: =IF(AND(E21="M",ISNUMBER(I21)),IF(I21>=3,1,0),0) -> 0
A22: A2.8 | B22: A2 | C22: Volunteer/auxiliary responder management system (accreditation, registry, deployment, insurance), incl. mobilization of ACDVs for anticipatory action | D22: RA 10121 Sec. 13; NDRRMC volunteer guidelines; RA 12287 IRR (2026) Rule IV Sec. 5 | E22: GP | F22: Volunteer registry; MOAs; accreditation | G22: DR, KII | H22: 1 | I22: 3 | J22: F: scored 3. DR: 10-Yr Plan SWOC says the volunteer roster is not institutionalised; ACDV roster/accreditation is a planned PPA. | K22: Validate: registry and accreditation records. ACDV mobilisation for AA (IRR Rule IV Sec. 5) not yet covered. | L22: Formalise the ACDV registry with accreditation, insurance and deployment rules, and add AA tasks for ACDVs. | M22: =IF(ISNUMBER(I22),(4-I22)*H22*IF(E22="M",1.5,1),"") -> 1 | N22: =IF(M22="","",IF(M22>=9,"High",IF(M22>=4,"Medium","Low"))) -> Low | O22: =IF(NOT(ISNUMBER(I22)),IF(I22="NA","N/A","Not scored"),IF(E22="M",IF(I22>=3,"Compliant","Non-compliant"),IF(I22>=3,"Meets GP","Below GP"))) -> Meets GP | P22: MOO Ch.6 | Q22: =IF(ISNUMBER(I22),I22*H22,0) -> 3 | R22: =IF(ISNUMBER(I22),4*H22,0) -> 4 | S22: =IF(ISNUMBER(I22),1,0) -> 1 | T22: =IF(AND(E22="M",ISNUMBER(I22)),1,0) -> 0 | U22: =IF(AND(E22="M",ISNUMBER(I22)),IF(I22>=3,1,0),0) -> 0
A23: A2.9 | B23: A2 | C23: Anticipatory action focal person designated in the CDRRMO, with AA training for staff, BDRRMCs, ACDVs and partner CSOs (incl. community-based early warning and early action) | D23: RA 12287 IRR (2026) Rule IV Sec. 1; Rule VII | E23: M | F23: Designation memo; training records | G23: DR | H23: 2 | I23: 0 | J23: DR: no AA focal-person designation found in the documents reviewed; F (A4.6): AA not yet in place locally. | K23: New mandatory item (IRR Rule IV Sec. 1; Rule VII). | L23: Designate an AA focal person by office order and enrol them, BDRRMC officers, ACDVs and partner CSOs in AA training when OCD VIII cascades the IRR. | M23: =IF(ISNUMBER(I23),(4-I23)*H23*IF(E23="M",1.5,1),"") -> 12 | N23: =IF(M23="","",IF(M23>=9,"High",IF(M23>=4,"Medium","Low"))) -> High | O23: =IF(NOT(ISNUMBER(I23)),IF(I23="NA","N/A","Not scored"),IF(E23="M",IF(I23>=3,"Compliant","Non-compliant"),IF(I23>=3,"Meets GP","Below GP"))) -> Non-compliant | P23: MOO Ch.2 / Ch.6 | Q23: =IF(ISNUMBER(I23),I23*H23,0) -> 0 | R23: =IF(ISNUMBER(I23),4*H23,0) -> 8 | S23: =IF(ISNUMBER(I23),1,0) -> 1 | T23: =IF(AND(E23="M",ISNUMBER(I23)),1,0) -> 1 | U23: =IF(AND(E23="M",ISNUMBER(I23)),IF(I23>=3,1,0),0) -> 0
A24: A2.10 | B24: A2 | C24: Inventory of DRRM-relevant skills across the CDRRMO, partner offices and barangays (SAR, engineering, logistics, GIS, PDNA, MHPSS) updated within the last 12 months | D24: UNDRR DRSC 6.1.1 | E24: GP | F24: Skills inventory with date | G24: DR | H24: 1 | I24: 1 | J24: F (Admin FGD, formerly under A1.3): lack of a database on personnel. DR: 10-Yr Plan volunteer roster not institutionalised. | K24: No skills inventory across CDRRMO, partner offices and barangays. | L24: Build a skills inventory (SAR, engineering, logistics, GIS, PDNA, MHPSS) covering CDRRMO, CDRRMC offices and BDRRMCs; update it every 12 months (UNDRR DRSC 6.1.1). | M24: =IF(ISNUMBER(I24),(4-I24)*H24*IF(E24="M",1.5,1),"") -> 3 | N24: =IF(M24="","",IF(M24>=9,"High",IF(M24>=4,"Medium","Low"))) -> Low | O24: =IF(NOT(ISNUMBER(I24)),IF(I24="NA","N/A","Not scored"),IF(E24="M",IF(I24>=3,"Compliant","Non-compliant"),IF(I24>=3,"Meets GP","Below GP"))) -> Below GP | P24: MOO Ch.6 | Q24: =IF(ISNUMBER(I24),I24*H24,0) -> 1 | R24: =IF(ISNUMBER(I24),4*H24,0) -> 4 | S24: =IF(ISNUMBER(I24),1,0) -> 1 | T24: =IF(AND(E24="M",ISNUMBER(I24)),1,0) -> 0 | U24: =IF(AND(E24="M",ISNUMBER(I24)),IF(I24>=3,1,0),0) -> 0
A25: A3 DRRM & CONTINGENCY PLANNING - LDRRMP, CPs, PSCP, mainstreaming in CDP/CLUP/LCCAP
A26: A3.1 | B26: A3 | C26: Local DRRM Plan (LDRRMP) current, approved by Sanggunian, aligned with NDRRMP 2020-2030 and Sendai Framework | D26: RA 10121 Sec. 12(c)(6); NDRRMP 2020-2030 | E26: M | F26: LDRRMP; SP resolution | G26: DR | H26: 3 | I26: 4 | J26: F: scored 4. DR: 10-Yr Plan adopted by SP Res. 2023-112, prepared with the NDRRMC 2022 LDRRMP guidebook. | K26: Validate the alignment table to NDRRMP 2020-2030 and Sendai. Barangay count in the plan (110) predates the 2022 merger; use 85. | L26: Maintain; in the next update correct the barangay count to 85 and add RA 12287 anticipatory action PPAs. | M26: =IF(ISNUMBER(I26),(4-I26)*H26*IF(E26="M",1.5,1),"") -> 0 | N26: =IF(M26="","",IF(M26>=9,"High",IF(M26>=4,"Medium","Low"))) -> Low | O26: =IF(NOT(ISNUMBER(I26)),IF(I26="NA","N/A","Not scored"),IF(E26="M",IF(I26>=3,"Compliant","Non-compliant"),IF(I26>=3,"Meets GP","Below GP"))) -> Compliant | P26: MOO Ch.3 Planning | Q26: =IF(ISNUMBER(I26),I26*H26,0) -> 12 | R26: =IF(ISNUMBER(I26),4*H26,0) -> 12 | S26: =IF(ISNUMBER(I26),1,0) -> 1 | T26: =IF(AND(E26="M",ISNUMBER(I26)),1,0) -> 1 | U26: =IF(AND(E26="M",ISNUMBER(I26)),IF(I26>=3,1,0),0) -> 1
A27: A3.2 | B27: A3 | C27: DRR-CCA mainstreamed in CDP, CLUP, ELA and LCCAP (hazard data used in land use and investment decisions) | D27: RA 10121 Sec. 2; RA 9729 as amended by RA 10174; HLURB/DHSUD CLUP guidelines | E27: M | F27: CDP, CLUP, LCCAP; LDIP/AIP tagging | G27: DR | H27: 2 | I27: 2 | J27: F: plans mainstreaming and provisions need review. DR: CLUP 2017-2027 has a DRRM-CCA sectoral chapter and fault/river easements, but no hazard overlay zones; it still uses 110 barangays and predates the CDRA. CDRA Final Report (TWG under EO 2023-0025) Ch.6 sets 8 Major Decision Areas to feed the CLUP, ZO, CDP, LCCAP, LDRRMP and LDRRMFIP. | K27: Assessor adjustment 3 -> 2 (conflicting evidence, take the lower): CDRA results are not yet carried into zoning overlays, a project screening step (C1.2) or the CDP/AIP. Restore to 3 when the updated CLUP/ZO is approved with CDRA overlays. | L27: Use the CLUP/ZO update to adopt CDRA hazard overlays and the MDA 1-8 interventions; tag CDP/AIP and LCCAP projects to CDRA risk-register entries; review mainstreaming in CDP, CLUP, ELA and LCCAP (see C1.1-C1.4). | M27: =IF(ISNUMBER(I27),(4-I27)*H27*IF(E27="M",1.5,1),"") -> 3 | N27: =IF(M27="","",IF(M27>=9,"High",IF(M27>=4,"Medium","Low"))) -> Low | O27: =IF(NOT(ISNUMBER(I27)),IF(I27="NA","N/A","Not scored"),IF(E27="M",IF(I27>=3,"Compliant","Non-compliant"),IF(I27>=3,"Meets GP","Below GP"))) -> Compliant | P27: MOO Ch.3 | Q27: =IF(ISNUMBER(I27),I27*H27,0) -> 6 | R27: =IF(ISNUMBER(I27),4*H27,0) -> 8 | S27: =IF(ISNUMBER(I27),1,0) -> 1 | T27: =IF(AND(E27="M",ISNUMBER(I27)),1,0) -> 1 | U27: =IF(AND(E27="M",ISNUMBER(I27)),IF(I27>=3,1,0),0) -> 1
A28: A3.3 | B28: A3 | C28: Hazard-specific Contingency Plans for priority hazards (flood/flash flood, landslide, earthquake/tsunami, tropical cyclone, industrial/geothermal), updated and tested | D28: NDRRMC CP guidelines; OCD CP Manual | E28: M | F28: CPs; simulation reports | G28: DR | H28: 3 | I28: 3 | J28: F: CPs updated but tested only for earthquake and flooding. DR: 10-Yr Plan says CPs exist but need updating; new CPs are planned. CDRA MDA 7 calls for hazard-specific CPs for flood, landslide, storm surge, earthquake and tsunami. | K28: No CPs for other top hazards (landslide, tsunami, tropical cyclone, geothermal/industrial); untested CPs. | L28: Prepare CPs for the remaining priority hazards and test each by tabletop; add AA annexes (A8.8) and pre-disaster recovery annex (A9.5). | M28: =IF(ISNUMBER(I28),(4-I28)*H28*IF(E28="M",1.5,1),"") -> 4.5 | N28: =IF(M28="","",IF(M28>=9,"High",IF(M28>=4,"Medium","Low"))) -> Medium | O28: =IF(NOT(ISNUMBER(I28)),IF(I28="NA","N/A","Not scored"),IF(E28="M",IF(I28>=3,"Compliant","Non-compliant"),IF(I28>=3,"Meets GP","Below GP"))) -> Compliant | P28: MOO Ch.3 / EOC Ch.3 | Q28: =IF(ISNUMBER(I28),I28*H28,0) -> 9 | R28: =IF(ISNUMBER(I28),4*H28,0) -> 12 | S28: =IF(ISNUMBER(I28),1,0) -> 1 | T28: =IF(AND(E28="M",ISNUMBER(I28)),1,0) -> 1 | U28: =IF(AND(E28="M",ISNUMBER(I28)),IF(I28>=3,1,0),0) -> 1
A29: A3.4 | B29: A3 | C29: Public Service Continuity Plan (PSCP) prepared covering CDRRMO and essential city services | D29: NDRRMC/OCD PSCP Guidebook | E29: M | F29: PSCP; BIA; essential functions list | G29: DR | H29: 2 | I29: 2 | J29: F: scored 2. DR: PSCP formulation is a 2023 PPA in 10-Yr Plan; NDRRMC/OCD PSCP Guidebook available. | K29: PSCP not completed; no BIA or essential-functions list sighted. | L29: Complete the PSCP using the PSCP Guidebook: essential functions, BIA, alternate site (links to B2.7), orders of succession, vital records. Exercise it once. | M29: =IF(ISNUMBER(I29),(4-I29)*H29*IF(E29="M",1.5,1),"") -> 6 | N29: =IF(M29="","",IF(M29>=9,"High",IF(M29>=4,"Medium","Low"))) -> Medium | O29: =IF(NOT(ISNUMBER(I29)),IF(I29="NA","N/A","Not scored"),IF(E29="M",IF(I29>=3,"Compliant","Non-compliant"),IF(I29>=3,"Meets GP","Below GP"))) -> Non-compliant | P29: MOO Ch.3 / EOC Ch.7 | Q29: =IF(ISNUMBER(I29),I29*H29,0) -> 4 | R29: =IF(ISNUMBER(I29),4*H29,0) -> 8 | S29: =IF(ISNUMBER(I29),1,0) -> 1 | T29: =IF(AND(E29="M",ISNUMBER(I29)),1,0) -> 1 | U29: =IF(AND(E29="M",ISNUMBER(I29)),IF(I29>=3,1,0),0) -> 0
A30: A3.5 | B30: A3 | C30: Annual LDRRMF Investment Plan (LDRRMFIP) prepared, approved and consistent with LDRRMP | D30: JMC 2013-1 | E30: M | F30: LDRRMFIP; CDRRMC resolution | G30: DR | H30: 3 | I30: 4 | J30: F: scored 4; LDRRMFIP prepared and approved. DR: 10-Yr Plan includes a 10-year LDRRMFIP of PHP 14.63 B (80% construction; 52% digital governance) with no anticipatory action line. | K30: Validate the CDRRMC resolution and link to LDRRMP PPAs. | L30: Maintain; add the AA line (A4.6) and EOC operations line (B7.5) explicitly. | M30: =IF(ISNUMBER(I30),(4-I30)*H30*IF(E30="M",1.5,1),"") -> 0 | N30: =IF(M30="","",IF(M30>=9,"High",IF(M30>=4,"Medium","Low"))) -> Low | O30: =IF(NOT(ISNUMBER(I30)),IF(I30="NA","N/A","Not scored"),IF(E30="M",IF(I30>=3,"Compliant","Non-compliant"),IF(I30>=3,"Meets GP","Below GP"))) -> Compliant | P30: MOO Ch.5 Financing | Q30: =IF(ISNUMBER(I30),I30*H30,0) -> 12 | R30: =IF(ISNUMBER(I30),4*H30,0) -> 12 | S30: =IF(ISNUMBER(I30),1,0) -> 1 | T30: =IF(AND(E30="M",ISNUMBER(I30)),1,0) -> 1 | U30: =IF(AND(E30="M",ISNUMBER(I30)),IF(I30>=3,1,0),0) -> 1
A31: A3.6 | B31: A3 | C31: Evacuation plan with mapped routes, safe zones, centers and pre-emptive evacuation triggers per barangay | D31: RA 10121; RA 12076; DILG Operation L!sto | E31: M | F31: Evacuation maps; plans per barangay | G31: DR, OBS | H31: 3 | I31: 2 | J31: F: incomplete. DR: 10-Yr Plan lists EC database/geotagging and Operation L!sto manual as PPAs; 46 barangays are critical flood barangays. | K31: Routes, maps and safe zones not aligned with SOPs; pre-emptive evacuation triggers per barangay missing. | L31: Produce barangay evacuation maps (routes, safe zones, ECs) for all 85 barangays, starting with the 46 critical flood barangays, and link triggers to the warning-action matrix (A6.2). | M31: =IF(ISNUMBER(I31),(4-I31)*H31*IF(E31="M",1.5,1),"") -> 9 | N31: =IF(M31="","",IF(M31>=9,"High",IF(M31>=4,"Medium","Low"))) -> High | O31: =IF(NOT(ISNUMBER(I31)),IF(I31="NA","N/A","Not scored"),IF(E31="M",IF(I31>=3,"Compliant","Non-compliant"),IF(I31>=3,"Meets GP","Below GP"))) -> Non-compliant | P31: MOO Ch.4 / EOC Ch.3 | Q31: =IF(ISNUMBER(I31),I31*H31,0) -> 6 | R31: =IF(ISNUMBER(I31),4*H31,0) -> 12 | S31: =IF(ISNUMBER(I31),1,0) -> 1 | T31: =IF(AND(E31="M",ISNUMBER(I31)),1,0) -> 1 | U31: =IF(AND(E31="M",ISNUMBER(I31)),IF(I31>=3,1,0),0) -> 0
A32: A3.7 | B32: A3 | C32: Barangay DRRM plans (85 barangays) reviewed/consolidated by CDRRMO | D32: RA 10121 Sec. 12(c)(6); DILG MC on BDRRM | E32: GP | F32: Consolidated BDRRMP status matrix | G32: DR | H32: 2 | I32: 4 | J32: F: SGLG-type compliance with good practice. | K32: Validate the consolidated BDRRMP status matrix for 85 barangays. | L32: Maintain; add AA and evacuation-map status columns to the matrix. | M32: =IF(ISNUMBER(I32),(4-I32)*H32*IF(E32="M",1.5,1),"") -> 0 | N32: =IF(M32="","",IF(M32>=9,"High",IF(M32>=4,"Medium","Low"))) -> Low | O32: =IF(NOT(ISNUMBER(I32)),IF(I32="NA","N/A","Not scored"),IF(E32="M",IF(I32>=3,"Compliant","Non-compliant"),IF(I32>=3,"Meets GP","Below GP"))) -> Meets GP | P32: MOO Ch.3 | Q32: =IF(ISNUMBER(I32),I32*H32,0) -> 8 | R32: =IF(ISNUMBER(I32),4*H32,0) -> 8 | S32: =IF(ISNUMBER(I32),1,0) -> 1 | T32: =IF(AND(E32="M",ISNUMBER(I32)),1,0) -> 0 | U32: =IF(AND(E32="M",ISNUMBER(I32)),IF(I32>=3,1,0),0) -> 0
A33: A4 DRRM FINANCING & FUND MANAGEMENT - LDRRMF allocation, utilization, QRF, trust fund, procurement
A34: A4.1 | B34: A4 | C34: LDRRMF set at not less than 5% of estimated revenue from regular sources | D34: RA 10121 Sec. 21; JMC 2013-1 | E34: M | F34: Annual budget; LDRRMF computation | G34: DR | H34: 3 | I34: 4 | J34: F: scored 4. | K34: Validate the LDRRMF computation (5% of estimated regular revenue). | L34: Maintain; keep the computation sheet with the budget. | M34: =IF(ISNUMBER(I34),(4-I34)*H34*IF(E34="M",1.5,1),"") -> 0 | N34: =IF(M34="","",IF(M34>=9,"High",IF(M34>=4,"Medium","Low"))) -> Low | O34: =IF(NOT(ISNUMBER(I34)),IF(I34="NA","N/A","Not scored"),IF(E34="M",IF(I34>=3,"Compliant","Non-compliant"),IF(I34>=3,"Meets GP","Below GP"))) -> Compliant | P34: MOO Ch.5 Financing | Q34: =IF(ISNUMBER(I34),I34*H34,0) -> 12 | R34: =IF(ISNUMBER(I34),4*H34,0) -> 12 | S34: =IF(ISNUMBER(I34),1,0) -> 1 | T34: =IF(AND(E34="M",ISNUMBER(I34)),1,0) -> 1 | U34: =IF(AND(E34="M",ISNUMBER(I34)),IF(I34>=3,1,0),0) -> 1
A35: A4.2 | B35: A4 | C35: 70% Mitigation/Preparedness and 30% Quick Response Fund (QRF) allocation observed | D35: RA 10121 Sec. 21; JMC 2013-1 | E35: M | F35: Appropriation ordinance; LDRRMFIP | G35: DR | H35: 3 | I35: 4 | J35: F: scored 4. | K35: Validate the appropriation ordinance. | L35: Maintain the 70/30 split; show the AA sub-allocation inside the 70% (A4.6). | M35: =IF(ISNUMBER(I35),(4-I35)*H35*IF(E35="M",1.5,1),"") -> 0 | N35: =IF(M35="","",IF(M35>=9,"High",IF(M35>=4,"Medium","Low"))) -> Low | O35: =IF(NOT(ISNUMBER(I35)),IF(I35="NA","N/A","Not scored"),IF(E35="M",IF(I35>=3,"Compliant","Non-compliant"),IF(I35>=3,"Meets GP","Below GP"))) -> Compliant | P35: MOO Ch.5 | Q35: =IF(ISNUMBER(I35),I35*H35,0) -> 12 | R35: =IF(ISNUMBER(I35),4*H35,0) -> 12 | S35: =IF(ISNUMBER(I35),1,0) -> 1 | T35: =IF(AND(E35="M",ISNUMBER(I35)),1,0) -> 1 | U35: =IF(AND(E35="M",ISNUMBER(I35)),IF(I35>=3,1,0),0) -> 1
A36: A4.3 | B36: A4 | C36: Unexpended LDRRMF transferred to Special Trust Fund and used within 5 years | D36: RA 10121 Sec. 21; COA Circular 2012-002 | E36: M | F36: STF ledger; COA reports | G36: DR | H36: 2 | I36: 4 | J36: F: scored 4. | K36: Validate the STF ledger and 5-year use. | L36: Maintain; list STF balances as an AA fund source (A4.6). | M36: =IF(ISNUMBER(I36),(4-I36)*H36*IF(E36="M",1.5,1),"") -> 0 | N36: =IF(M36="","",IF(M36>=9,"High",IF(M36>=4,"Medium","Low"))) -> Low | O36: =IF(NOT(ISNUMBER(I36)),IF(I36="NA","N/A","Not scored"),IF(E36="M",IF(I36>=3,"Compliant","Non-compliant"),IF(I36>=3,"Meets GP","Below GP"))) -> Compliant | P36: MOO Ch.5 | Q36: =IF(ISNUMBER(I36),I36*H36,0) -> 8 | R36: =IF(ISNUMBER(I36),4*H36,0) -> 8 | S36: =IF(ISNUMBER(I36),1,0) -> 1 | T36: =IF(AND(E36="M",ISNUMBER(I36)),1,0) -> 1 | U36: =IF(AND(E36="M",ISNUMBER(I36)),IF(I36>=3,1,0),0) -> 1
A37: A4.4 | B37: A4 | C37: LDRRMF utilization rate monitored and reported (target >= 80% of current-year 70% fund) | D37: JMC 2013-1; COA AAR findings | E37: GP | F37: Utilization reports; COA AAR | G37: DR | H37: 2 | I37: 3 | J37: F: 80% utilisation not yet met; monitoring needed. DR: 10-Yr Plan SWOC notes QRF utilisation/accessibility is a challenge. | K37: Utilisation below target. | L37: Track LDRRMF utilisation quarterly in the CDRRMC meeting; flag PPAs at risk by Q3. | M37: =IF(ISNUMBER(I37),(4-I37)*H37*IF(E37="M",1.5,1),"") -> 2 | N37: =IF(M37="","",IF(M37>=9,"High",IF(M37>=4,"Medium","Low"))) -> Low | O37: =IF(NOT(ISNUMBER(I37)),IF(I37="NA","N/A","Not scored"),IF(E37="M",IF(I37>=3,"Compliant","Non-compliant"),IF(I37>=3,"Meets GP","Below GP"))) -> Meets GP | P37: MOO Ch.5 | Q37: =IF(ISNUMBER(I37),I37*H37,0) -> 6 | R37: =IF(ISNUMBER(I37),4*H37,0) -> 8 | S37: =IF(ISNUMBER(I37),1,0) -> 1 | T37: =IF(AND(E37="M",ISNUMBER(I37)),1,0) -> 0 | U37: =IF(AND(E37="M",ISNUMBER(I37)),IF(I37>=3,1,0),0) -> 0
A38: A4.5 | B38: A4 | C38: Emergency procurement procedures (negotiated procurement - emergency cases) documented and pre-arranged (framework agreements, pre-qualified suppliers) | D38: RA 12009 (New Government Procurement Act) & IRR | E38: M | F38: Procurement SOP; framework agreements | G38: DR, KII | H38: 2 | I38: 3 | J38: F: local suppliers' capability needs regular updating. | K38: Supplier list not refreshed; framework agreements to be confirmed. | L38: Keep a pre-qualified supplier list updated each year; set framework agreements for relief goods, fuel and heavy equipment under RA 12009 IRR, usable for AA (B6.6). | M38: =IF(ISNUMBER(I38),(4-I38)*H38*IF(E38="M",1.5,1),"") -> 3 | N38: =IF(M38="","",IF(M38>=9,"High",IF(M38>=4,"Medium","Low"))) -> Low | O38: =IF(NOT(ISNUMBER(I38)),IF(I38="NA","N/A","Not scored"),IF(E38="M",IF(I38>=3,"Compliant","Non-compliant"),IF(I38>=3,"Meets GP","Below GP"))) -> Compliant | P38: MOO Ch.5 / EOC Ch.6 | Q38: =IF(ISNUMBER(I38),I38*H38,0) -> 6 | R38: =IF(ISNUMBER(I38),4*H38,0) -> 8 | S38: =IF(ISNUMBER(I38),1,0) -> 1 | T38: =IF(AND(E38="M",ISNUMBER(I38)),1,0) -> 1 | U38: =IF(AND(E38="M",ISNUMBER(I38)),IF(I38>=3,1,0),0) -> 1
